Workbook

Sheet 任务库
A1: ID | B1: 历史事件类型 | C1: 任务名称 | D1: 任务描述 | E1: 只展示完成与否情况 | F1: 行为ID | G1: 目标值 | H1: 初始值 | I1: 事件参数 | J1: 持续时间类型 | K1: *说明持续时间类型 | L1: *时间开始 | M1: *时间结束 | N1: 检测值 | O1: *说明一下检测值 | P1: 检测操作 | Q1: *说明一下检测操作 | R1: 奖励
A2: 0 | B2: 101 | C2: Tên 1 | D2: Miêu tả 1 | F2: 2 | G2: 5 | J2: 0 | K2: 枚举如下： | N2: 0 | O2: 是指通过数据的哪一部分 | P2: 2 | Q2: 是指如何判断数据 | R2: 0:1:100#0:2:100
A3: 2 | B3: 201 | C3: Tên 2 | D3: Miêu tả 2 | F3: 2 | G3: 10 | J3: 0 | K3: 0：永久 | N3: 0 | O3: 去检测任务已完成 | P3: 2 | Q3: 与任务要求的数据 | R3: 0:1:100#0:2:101
A4: 3 | B4: 201 | C4: Tên 3 | D4: Miêu tả 3 | F4: 2 | G4: 11 | J4: 0 | K4: 1：每日（0点清空数据） | N4: 0 | O4: 枚举如下： | P4: 2 | Q4: 相满足 | R4: 0:1:100#0:2:102
A5: 4 | B5: 201 | C5: Tên 4 | D5: Miêu tả 4 | F5: 2 | G5: 12 | J5: 0 | K5: 2：每周（周一0点清空数据） | N5: 0 | O5: 0：以当前值进行比较 | P5: 2 | Q5: 枚举如下： | R5: 0:1:100#0:2:103
A6: 5 | B6: 201 | C6: Tên 5 | D6: Miêu tả 5 | F6: 2 | G6: 13 | J6: 0 | K6: 3：每月（1号0点清空数据） | N6: 2 | O6: 1：以最小值进行比较 | P6: 2 | Q6: 0：检测值=目标值 | R6: 0:1:100#0:2:104
A7: 6 | B7: 201 | C7: Tên 6 | D7: Miêu tả 6 | F7: 2 | G7: 14 | J7: 0 | K7: 4：一段时间（只接收这段时间的数据） | N7: 0 | O7: 2：以最大值进行比较 | P7: 2 | Q7: 1：检测值<=目标值 | R7: 0:1:100#0:2:105
A8: 7 | B8: 201 | C8: Tên 7 | D8: Miêu tả 7 | F8: 2 | G8: 15 | J8: 0 | K8: 默认使用永久历史 | N8: 0 | P8: 2 | Q8: 2：检测值>=目标值 | R8: 0:1:100#0:2:106
A9: 8 | B9: 201 | C9: Tên 8 | D9: Miêu tả 8 | F9: 2 | G9: 16 | J9: 0 | N9: 0 | O9: 很多时候用当前值也行用最大值也行 | P9: 2 | Q9: 什么时候会用到1呢？ | R9: 0:1:100#0:2:107
A10: 9 | B10: 201 | C10: Tên 9 | D10: Miêu tả 9 | F10: 2 | G10: 17 | J10: 0 | N10: 0 | O10: 这是正常的 | P10: 2 | Q10: 比如3回合内通关 | R10: 0:1:100#0:2:108
A11: 10 | B11: 201 | C11: Tên 10 | D11: Miêu tả 10 | F11: 2 | G11: 18 | J11: 0 | N11: 2 | P11: 2 | R11: 0:1:100#0:2:200
A12: 11 | B12: 201 | C12: Tên 11 | D12: Miêu tả 11 | F12: 2 | G12: 19 | J12: 0 | N12: 0 | P12: 2 | R12: 0:1:100#0:2:292
A13: 12 | B13: 201 | C13: Tên 12 | D13: Miêu tả 12 | F13: 2 | G13: 20 | J13: 0 | N13: 0 | P13: 2 | R13: 0:1:100#0:2:384
A14: 13 | B14: 9999 | C14: Tên 13 | D14: Miêu tả 13 | G14: 5 | J14: 1 | N14: 2 | P14: 2 | R14: 0:1:100#0:15:10
A15: 14 | B15: 9999 | C15: Tên 14 | D15: Miêu tả 14 | G15: 3 | J15: 1 | N15: 2 | P15: 2 | R15: 0:1:100#0:15:15
A16: 15 | B16: 9999 | C16: Tên 15 | D16: Miêu tả 15 | G16: 3 | J16: 1 | N16: 2 | P16: 2 | R16: 0:1:100#0:15:15
A17: 16 | B17: 9999 | C17: Tên 16 | D17: Miêu tả 16 | G17: 3 | J17: 1 | N17: 2 | P17: 2 | R17: 0:1:100#0:15:10
A18: 17 | B18: 9999 | C18: Tên 17 | D18: Miêu tả 17 | G18: 1 | J18: 1 | N18: 2 | P18: 2 | R18: 0:1:100#0:15:10
A19: 18 | B19: 9999 | C19: Tên 18 | D19: Miêu tả 18 | G19: 2 | J19: 1 | N19: 2 | P19: 2 | R19: 0:1:100#0:15:25
A20: 19 | B20: 9999 | C20: Tên 19 | D20: Miêu tả 19 | G20: 3 | J20: 1 | N20: 2 | P20: 2 | R20: 0:1:100#0:15:20
A21: 20 | B21: 9999 | C21: Tên 20 | D21: Miêu tả 20 | G21: 3 | J21: 1 | N21: 2 | P21: 2 | R21: 0:1:100#0:15:30
A22: 21 | B22: 9999 | C22: Tên 21 | D22: Miêu tả 21 | G22: 2 | J22: 1 | N22: 2 | P22: 2 | R22: 0:1:100#0:15:10
A23: 22 | B23: 9999 | C23: Tên 22 | D23: Miêu tả 22 | G23: 1 | J23: 1 | N23: 2 | P23: 2 | R23: 0:1:100#0:15:5
A24: 23 | B24: 201 | C24: Tên 23 | D24: Miêu tả 23 | F24: 2 | G24: 21 | J24: 0 | N24: 2 | P24: 2 | R24: 0:1:100#0:2:292
A25: 24 | B25: 9999 | C25: Tên 24 | D25: Miêu tả 24 | G25: 15 | J25: 4 | L25: 2019-09-11 00:00:00 | M25: 2019-09-11 12:00:00 | N25: 2 | P25: 2 | R25: 0:1:100#0:2:384
A26: 1001 | B26: 101 | C26: Đăng nhập | D26: Hôm nay đăng nhập | G26: 1 | J26: 1 | N26: 2 | P26: 2 | R26: 0:15:5#0:1:20
A27: 1002 | B27: 302 | C27: Tặng quà bạn bè | D27: Tặng 5 quà bạn bè | F27: 1 | G27: 5 | J27: 1 | N27: 2 | P27: 2 | R27: 0:15:5#0:5:100
A28: 1003 | B28: 401 | C28: Triệu hoán | D28: Triệu hoán 3 lần | F28: 2 | G28: 3 | J28: 1 | N28: 2 | P28: 2 | R28: 0:15:10#0:1:20
A29: 1004 | B29: 1211 | C29: Tiên minh phó bản | D29: Phó bản tiên minh 3 lần | F29: 17 | G29: 3 | J29: 1 | N29: 2 | P29: 2 | R29: 0:15:15#0:12:50
A30: 1005 | B30: 1202 | C30: Tiên minh hiến tặng | D30: Hiến tặng tiên minh 3 lần | F30: 18 | G30: 1 | J30: 1 | N30: 2 | P30: 2 | R30: 0:15:10#3:100021:1
A31: 1006 | B31: 1402 | C31: Vô tận luân hồi | D31: Khiêu chiến 1 lần vô tận luân hồi | F31: 3 | G31: 1 | J31: 1 | N31: 2 | P31: 2 | R31: 0:15:10#3:100005:1
A32: 1007 | B32: 1003 | C32: Nhiệm vụ treo thưởng | D32: Làm 1 nhiệm vụ treo thưởng | F32: 4 | G32: 3 | J32: 1 | N32: 2 | P32: 2 | R32: 0:15:10#0:0:40000
A33: 1008 | B33: 1101 | C33: Phó bản ngày | D33: Khiêu chiến 2 ngày kế tiếp thường phó bản | F33: 5 | G33: 2 | J33: 1 | N33: 2 | P33: 2 | R33: 0:15:10#3:100005:1
A34: 1009 | B34: 1502 | C34: Côn Luân bí cảnh | D34: Côn luân bí cảnh thắng lợi 3 lần | F34: 6 | G34: 3 | J34: 1 | N34: 2 | P34: 2 | R34: 0:15:15#0:0:30000
A35: 1010 | B35: 1301 | C35: Linh Lung Tháp | D35: Khiêu chiến linh lung tháp 3 lần | F35: 7 | G35: 3 | J35: 1 | N35: 2 | P35: 2 | R35: 0:15:10#3:100001:20
A36: 1011 | B36: 3101 | C36: Đấu trường | D36: Tham dự 3 lần đấu trường khiêu chiến | F36: 9 | G36: 3 | J36: 1 | N36: 2 | P36: 2 | R36: 0:15:15#3:100023:2
A37: 1012 | B37: 1002 | C37: Chiến nhanh | D37: Chiến nhanh 3 lần | F37: 10 | G37: 3 | J37: 1 | N37: 2 | P37: 2 | R37: 0:15:15#0:1:30
A38: 1013 | B38: 1002 | C38: Chiến nhanh | D38: Chiến nhanh 1 lần | F38: 10 | G38: 1 | J38: 0 | N38: 2 | P38: 2 | R38: 0:15:15#0:1:50
... A57: 1117 | B57: 201 | C57: Nhân vật đạt cấp | D57: Đạt cấp 20 | F57: 33 | G57: 20 | J57: 0 | N57: 2 | P57: 2 | R57: 0:0:50000#0:1:500
A58: 1201 | B58: 430 | C58: Anh hùng thăng cấp Ⅰ | D58: Có 1 anh hùng đạt cấp 30 | F58: 44 | G58: 1 | I58: 30 | J58: 0 | N58: 2 | P58: 2 | R58: 0:0:50000#0:1:100
...

Sheet 永久历史
A1: ID | B1: 这代表什么 | C1: 事件类型 | D1: 事件参数 | E1: 重要说明
A2: 1 | B2: Đăng nhập trò chơi số lần | C2: 101 | E2: 在实质内容层面：事件类型+参数构成唯一主键，因此，事件类型+参数，要具有唯一性
A3: 2 | B3: Nhân vật chính mạo hiểm đẳng cấp | C3: 201
A4: 3 | B4: [ Tính gộp lại ] Đưa tặng hảo hữu hữu nghị điểm số lần | C4: 302
A5: 4 | B5: [ Tính gộp lại ] Anh hùng triệu hoán số lần | C5: 401
A6: 5 | B6: [ Tính gộp lại ] Hợp thành 6 Tinh anh hùng số lượng | C6: 403 | D6: 6
A7: 6 | B7: [ Tính gộp lại ] Hợp thành 8 Tinh anh hùng số lượng | C7: 403 | D7: 8
A8: 7 | B8: n Anh hùng đạt tới 30 Cấp | C8: 430 | D8: 30
A9: 8 | B9: n Anh hùng đạt tới 40 Cấp | C9: 430 | D9: 40
A10: 9 | B10: n Anh hùng đạt tới 50 Cấp | C10: 430 | D10: 50
A11: 10 | B11: n Anh hùng đạt tới 60 Cấp | C11: 430 | D11: 60
A12: 11 | B12: n Anh hùng đạt tới 80 Cấp | C12: 430 | D12: 80
A13: 12 | B13: n Anh hùng đạt tới 100 Cấp | C13: 430 | D13: 100
A14: 13 | B14: n Anh hùng đạt tới 145 Cấp | C14: 430 | D14: 145
A15: 14 | B15: n Anh hùng đạt tới 165 Cấp | C15: 430 | D15: 165
A16: 15 | B16: n Anh hùng đạt tới 185 Cấp | C16: 430 | D16: 185
A17: 16 | B17: n Anh hùng đạt tới 205 Cấp | C17: 430 | D17: 205
... A23: 22 | B23: [ Tính gộp lại ] Cao cấp triệu hoán anh hùng số lần | C23: 402 | D23: 2
A24: 23 | B24: [ Tính gộp lại ] Hiểu số mệnh con người xem đoán xâm số lần | C24: 405
A25: 24 | B25: [ Tính gộp lại ] Anh hùng phân giải số lượng | C25: 404
A26: 25 | B26: Có được hảo hữu số lượng | C26: 301
A27: 26 | B27: Có được n Kiện tử sắc phẩm chất trang bị | C27: 601 | D27: 3
A28: 27 | B28: Có được n Kiện màu cam phẩm chất trang bị | C28: 601 | D28: 4
A29: 28 | B29: Có được n Kiện màu đỏ phẩm chất trang bị | C29: 601 | D29: 5
A30: 29 | B30: Tính gộp lại tiến hành n Lần tỉ ấn hợp thành | C30: 502
A31: 30 | B31: đấu trường điểm tích lũy đạt tới n | C31: 3102
A32: 31 | B32: đấu trường xếp hạng | C32: 3103
A33: 32 | B33: Khiêu chiến thường ngày phó bản số lần | C33: 1101
A34: 33 | B34: [ Tính gộp lại ] Xác nhận x Lần tử sắc phẩm chất chạy thương nhiệm vụ | C34: 1004 | D34: 3
A35: 34 | B35: [ Tính gộp lại ] Xác nhận x Lần màu cam phẩm chất chạy thương nhiệm vụ | C35: 1004 | D35: 4
A36: 35 | B36: [ Tính gộp lại ] Xác nhận x Lần màu đỏ phẩm chất chạy thương nhiệm vụ | C36: 1004 | D36: 5
A37: 36 | B37: Côn Luân bí cảnh ( Tùy ý độ khó ) Thắng lợi n Lần | C37: 1502
A38: 37 | B38: Sáng tạo hoặc gia nhập tiên minh | C38: 1201
A39: 38 | B39: [ Tính gộp lại ] Khiêu chiến n Lần tiên minh phó bản | C39: 1211
A40: 39 | B40: Tại PVP Chiến đấu bên trong, 8 Hiệp nội chiến thắng chiến lực cao hơn đối thủ của mình n Lần | C40: 3001 | D40: 8
A41: 40 | B41: Tại PVP Chiến đấu bên trong, 7 Hiệp nội chiến thắng chiến lực cao hơn đối thủ của mình n Lần | C41: 3001 | D41: 7
A42: 41 | B42: Tại PVP Chiến đấu bên trong, 6 Hiệp nội chiến thắng chiến lực cao hơn đối thủ của mình n Lần | C42: 3001 | D42: 6
A43: 42 | B43: Tại PVP Chiến đấu bên trong, chiến thắng chiến lực cao hơn tự thân 10 Vạn đối thủ n Lần | C43: 3002 | D43: 100000
A44: 43 | B44: Tại PVP Chiến đấu bên trong, chiến thắng chiến lực cao hơn tự thân 20 Vạn đối thủ n Lần | C44: 3002 | D44: 200000
A45: 44 | B45: Tại PVP Chiến đấu bên trong, chiến thắng chiến lực cao hơn tự thân 30 Vạn đối thủ n Lần | C45: 3002 | D45: 300000
...

Sheet 主线任务
A1: ID | B1: 任务ID | C1: 下一个任务ID | D1: *任务内容备注 | E1: 引导ID | F1: 接取任务后是否出现引导手指
A2: 1 | B2: 100000 | C2: 290001 | D2: Vượt ải chính tuyến 1 | E2: 1
A3: 2 | B3: 290001 | C3: 1700 | D3: Nhận lấy một lần thông ban thưởng | E3: 12
A4: 3 | B4: 1700 | C4: 300001 | D4: Tiến hành 1 lần anh hùng triệu hoán | E4: 2
A5: 4 | B5: 300001 | C5: 100001 | D5: Ra trận một cái mới anh hùng | E5: 3
A6: 5 | B6: 100001 | C6: 101001 | D6: Vượt ải chính tuyến 2 | F6: 1
A7: 6 | B7: 101001 | C7: 130000 | D7: Vượt ải luyên tuyến anh hùng 1 | E7: 34
A8: 7 | B8: 130000 | C8: 100002 | D8: 1 Anh hùng đạt tới 10 Cấp | E8: 4
A9: 8 | B9: 100002 | C9: 140001 | D9: Vượt ải chính tuyến 3 | E9: 5
A10: 9 | B10: 140001 | C10: 100003 | D10: Mặc 1 lần trang bị | E10: 6
A11: 10 | B11: 100003 | C11: 101002 | D11: Vượt ải chính tuyến 4 | E11: 7
A12: 11 | B12: 101002 | C12: 100036 | D12: Vượt ải luyên tuyến anh hùng 2 | F12: 1
A13: 12 | B13: 100036 | C13: 1013 | D13: Vượt ải chính tuyến 5 | F13: 1
A14: 13 | B14: 1013 | C14: 80001 | D14: Nhanh chóng tác chiến 1 lần | E14: 9
A15: 14 | B15: 80001 | C15: 130001 | D15: Mở ra đặc quyền cửa hàng | E15: 31
A16: 15 | B16: 130001 | C16: 100004 | D16: 1 Anh hùng đạt tới 30 Cấp | E16: 10
A17: 16 | B17: 100004 | C17: 240001 | D17: Vượt ải chính tuyến 6 | E17: 11
A18: 17 | B18: 240001 | C18: 100005 | D18: Hợp thành 1 lần trang bị | E18: 13
A19: 18 | B19: 100005 | C19: 999997 | D19: Vượt ải chính tuyến 8 | E19: 27
A20: 19 | B20: 999997 | C20: 100034 | D20: Anh hùng tiến giai | E20: 23
A21: 20 | B21: 100034 | C21: 999995 | D21: Vượt ải chính tuyến 9 | F21: 1
A22: 21 | B22: 999995 | C22: 100006 | D22: Cây bồ đề tưới nước 1 lần | E22: 26
A23: 22 | B23: 100006 | C23: 120001 | D23: Vượt ải chính tuyến 10 | F23: 1
A24: 23 | B24: 120001 | C24: 3601 | D24: Kích hoạt Hiên Viên Kiếm | E24: 14
A25: 24 | B25: 3601 | C25: 1711 | D25: Mặc 1 Món pháp bảo | E25: 24
A26: 25 | B26: 1711 | C26: 170001 | D26: Lại tiến hành 1 lần anh hùng triệu hoán | E26: 25
A27: 26 | B27: 170001 | C27: 100035 | D27: Xác nhận 1 lần treo thưởng nhiệm vụ | E27: 15
A28: 27 | B28: 100035 | C28: 100008 | D28: Vượt ải chính tuyến 14
A29: 28 | B29: 100008 | C29: 80002 | D29: Vượt ải chính tuyến 15 | E29: 32
A30: 29 | B30: 80002 | C30: 260001 | D30: Nhận lấy 5 Tinh anh hùng mảnh vỡ | E30: 29
A31: 30 | B31: 260001 | C31: 999994 | D31: Khiêu chiến 1 lần đấu trường | E31: 16
A32: 31 | B32: 999994 | C32: 80004 | D32: Nhận lấy một lần thành tựu ban thưởng | E32: 28
A33: 32 | B33: 80004 | C33: 120002 | D33: Hiểu rõ treo thưởng đặc quyền | E33: 33
A34: 33 | B34: 120002 | C34: 100010 | D34: Kích hoạt Bàn Cổ Phủ | F34: 1
A35: 34 | B35: 100010 | C35: 130004 | D35: Vượt ải chính tuyến 18 | F35: 1
A36: 35 | B36: 130004 | C36: 100011 | D36: 2 Anh hùng đạt tới 40 Cấp | F36: 1
A37: 36 | B37: 100011 | C37: 120003 | D37: Vượt ải chính tuyến 20 | F37: 1
A38: 37 | B38: 120003 | C38: 130005 | D38: Kích hoạt Bỉ Ngạn Hoa | F38: 1
A39: 38 | B39: 130005 | C39: 100013 | D39: 1 Anh hùng đạt tới 50 Cấp | F39: 1
A40: 39 | B40: 100013 | C40: 3201 | D40: Vượt ải chính tuyến 30 | F40: 1
...

Sheet 日常任务
A1: 任务ID | B1: 功能ID | C1: 排序ID | D1: *名称(备注)
A2: 1001 | C2: 1 | D2: =VLOOKUP(A2,任务库!A:C,3,0) -> Đăng nhập
A3: 1002 | B3: 900 | C3: 2 | D3: =VLOOKUP(A3,任务库!A:C,3,0) -> Tặng quà bạn bè
A4: 1003 | B4: 2100 | C4: 3 | D4: =VLOOKUP(A4,任务库!A:C,3,0) -> Triệu hoán
A5: 1004 | B5: 3002 | C5: 4 | D5: =VLOOKUP(A5,任务库!A:C,3,0) -> Tiên minh phó bản
A6: 1005 | B6: 3000 | C6: 5 | D6: =VLOOKUP(A6,任务库!A:C,3,0) -> Tiên minh hiến tặng
A7: 1006 | B7: 1100 | C7: 6 | D7: =VLOOKUP(A7,任务库!A:C,3,0) -> Vô tận luân hồi
A8: 1007 | C8: 7 | D8: =VLOOKUP(A8,任务库!A:C,3,0) -> Nhiệm vụ treo thưởng
A9: 1008 | B9: 4000 | C9: 8 | D9: =VLOOKUP(A9,任务库!A:C,3,0) -> Phó bản ngày
A10: 240002 | C10: 9 | D10: =VLOOKUP(A10,任务库!A:C,3,0) -> Trang bị hợp thành
A11: 1010 | B11: 1080 | C11: 10 | D11: =VLOOKUP(A11,任务库!A:C,3,0) -> Linh Lung Tháp
A12: 1011 | B12: 1090 | C12: 11 | D12: =VLOOKUP(A12,任务库!A:C,3,0) -> Đấu trường
A13: 1012 | C13: 12 | D13: =VLOOKUP(A13,任务库!A:C,3,0) -> Chiến nhanh

Sheet 日常任务宝箱
A1: 宝箱ID | B1: 活跃度 | C1: 奖励
A2: 1 | B2: 25 | C2: 0:1:200#0:0:10000
A3: 2 | B3: 50 | C3: 0:1:300#3:100021:2
A4: 3 | B4: 75 | C4: 0:1:700#3:100005:1
A5: 4 | B5: 100 | C5: 0:1:800#0:0:50000

Sheet 周常任务
A1: 任务ID | B1: 功能ID | C1: 排序ID | D1: *名称(备注)
A2: 580001 | B2: 2120 | C2: 1 | D2: Đoán xâm 1 Lần
A3: 580002 | B3: 890 | C3: 2 | D3: Cao cấp tầm bảo 1l
A4: 580003 | C4: 3 | D4: Tỉ ấn hợp thành 3l
A5: 580004 | C5: 4 | D5: Tàng Bảo Các hối đoái 15l
A6: 580005 | B6: 9000 | C6: 5 | D6: Dự đoán giải quán quân 4l
A7: 580006 | C7: 6 | D7: Thăng cấp đẳng cấp pháp bảo 1l
A8: 580007 | C8: 7 | D8: Tỉ ấn đúc lại 1l
A9: 580008 | B9: 5000 | C9: 8 | D9: Thú hồn tẩy luyện 1l
A10: 580009 | B10: 5000 | C10: 9 | D10: Sơn Hải kinh khiêu chiến thắng lợi 2l
A11: 580010 | B11: 5000 | C11: 10 | D11: Thú hồn cầu nguyện 3l
A12: 580012 | B12: 10010 | C12: 12 | D12: Tính gộp lại đánh dấu 5l
A13: 580013 | B13: 710 | C13: 13 | D13: Nạp tiền tùy ý
A14: 580014 | B14: 8600 | C14: 14 | D14: Đồ đằng Thánh Điện khiêu chiến thành công 15l

Sheet 周常任务宝箱
A1: 宝箱ID | B1: 活跃度 | C1: 奖励
A2: 1 | B2: 25 | C2: 3:100001:200#3:1000001:1#0:1:200
A3: 2 | B3: 50 | C3: 3:100003:1#3:100030:10000#0:1:300
A4: 3 | B4: 75 | C4: 0:1:200#3:100004:500#0:1:1000
A5: 4 | B5: 100 | C5: 3:100022:2#3:100001:200#0:1:3500

Sheet 成就
A1: 任务ID | B1: 分组 | C1: 次序 | D1: *备注
A2: 1114 | B2: 1 | C2: 1 | D2: =VLOOKUP(A2,任务库!A:D,4,0) -> Đạt cấp 5
A3: 1115 | B3: 1 | C3: 2 | D3: =VLOOKUP(A3,任务库!A:D,4,0) -> Đạt cấp 10
A4: 1116 | B4: 1 | C4: 3 | D4: =VLOOKUP(A4,任务库!A:D,4,0) -> Đạt cấp 15
A5: 1117 | B5: 1 | C5: 4 | D5: =VLOOKUP(A5,任务库!A:D,4,0) -> Đạt cấp 20
A6: 1101 | B6: 1 | C6: 5 | D6: =VLOOKUP(A6,任务库!A:D,4,0) -> Đạt cấp 30
A7: 1102 | B7: 1 | C7: 6 | D7: =VLOOKUP(A7,任务库!A:D,4,0) -> Đạt cấp 40
A8: 1103 | B8: 1 | C8: 7 | D8: =VLOOKUP(A8,任务库!A:D,4,0) -> Đạt cấp 50
A9: 1104 | B9: 1 | C9: 8 | D9: =VLOOKUP(A9,任务库!A:D,4,0) -> Đạt cấp 60
A10: 1105 | B10: 1 | C10: 9 | D10: =VLOOKUP(A10,任务库!A:D,4,0) -> Đạt cấp 70
A11: 1106 | B11: 1 | C11: 10 | D11: =VLOOKUP(A11,任务库!A:D,4,0) -> Đạt cấp 80
A12: 1107 | B12: 1 | C12: 11 | D12: =VLOOKUP(A12,任务库!A:D,4,0) -> Đạt cấp 90
A13: 1108 | B13: 1 | C13: 12 | D13: =VLOOKUP(A13,任务库!A:D,4,0) -> Đạt cấp 100
... A169: 3405 | B169: 26 | C169: 5 | D169: =VLOOKUP(A169,任务库!A:D,4,0) -> 20 lần tiên minh phó bản boss

Sheet 历练
A1: 任务ID | B1: 分类 | C1: 次序 | D1: *备注
A2: 10001 | B2: 1 | C2: 1 | D2: =VLOOKUP(A2,任务库!A:D,4,0) -> Tại pvp chiến đấu bên trong, 8 hiệp nội chiến thắng chiến lực cao hơn đối thủ của mình 5 lần
A3: 10002 | B3: 1 | C3: 2 | D3: =VLOOKUP(A3,任务库!A:D,4,0) -> Tại pvp chiến đấu bên trong, 7 hiệp nội chiến thắng chiến lực cao hơn đối thủ của mình 4 lần
A4: 10003 | B4: 1 | C4: 3 | D4: =VLOOKUP(A4,任务库!A:D,4,0) -> Tại pvp chiến đấu bên trong, 6 hiệp nội chiến thắng chiến lực cao hơn đối thủ của mình 3 lần
A5: 11001 | B5: 1 | C5: 4 | D5: =VLOOKUP(A5,任务库!A:D,4,0) -> Tại pvp chiến đấu bên trong, chiến thắng chiến lực cao hơn tự thân 10 vạn đối thủ 20 lần
A6: 11002 | B6: 1 | C6: 5 | D6: =VLOOKUP(A6,任务库!A:D,4,0) -> Tại pvp chiến đấu bên trong, chiến thắng chiến lực cao hơn tự thân 20 vạn đối thủ 15 lần
A7: 11003 | B7: 1 | C7: 6 | D7: =VLOOKUP(A7,任务库!A:D,4,0) -> Tại pvp chiến đấu bên trong, chiến thắng chiến lực cao hơn tự thân 30 vạn đối thủ 10 lần
A8: 12001 | B8: 1 | C8: 7 | D8: =VLOOKUP(A8,任务库!A:D,4,0) -> Tại pvp chiến đấu bên trong, đầy máu đủ quân số chiến thắng chiến lực cao hơn tự thân đối thủ 10 lần
A9: 13001 | B9: 1 | C9: 8 | D9: =VLOOKUP(A9,任务库!A:D,4,0) -> Tại pvp chiến đấu bên trong, sử dụng pháp bảo tính gộp lại đánh giết địch quân anh hùng 100 lần
A10: 14001 | B10: 1 | C10: 9 | D10: =VLOOKUP(A10,任务库!A:D,4,0) -> Tại pvp chiến đấu bên trong, sử dụng hạo thiên chùy tính gộp lại mê muội 200 cái địch quân anh hùng
A11: 15001 | B11: 1 | C11: 10 | D11: =VLOOKUP(A11,任务库!A:D,4,0) -> Tại đơn trận pvp chiến đấu bên trong sử dụng kỹ năng chủ động phục sinh phe mình anh hùng 3 lần
A12: 16001 | B12: 1 | C12: 11 | D12: =VLOOKUP(A12,任务库!A:D,4,0) -> Tại đơn trận pvp chiến đấu bên trong tổng trị liệu lượng đạt tới 500 vạn
A13: 17001 | B13: 2 | C13: 12 | D13: =VLOOKUP(A13,任务库!A:D,4,0) -> Linh lung tháp vượt tầng 200
... A53: 34003 | B53: 3 | C53: 52 | D53: =VLOOKUP(A53,任务库!A:D,4,0) -> Sở hữu 10 cái tỉ ấn đỏ

Sheet Sheet缺少的事件类型
B2: Thông Thiên tháp | C2: Thông Thiên tháp lịch sử tối cao thông quan số đạt tới X Quan
B3: Viễn chinh | C3: Tính gộp lại thông quan X Lần độ khó N Viễn chinh phó bản ( Đánh xong toàn bộ cửa ải tính 1 Lần thông quan )
B4: Tính gộp lại trúng độc tổn thương | C4: Đơn cuộc chiến đấu tính gộp lại tạo thành X Điểm trúng độc thương hại (PVP, PVE Chiến đấu đều tính, hảo hữu luận bàn không tính )
B5: Tính gộp lại thiêu đốt tổn thương | C5: Đơn cuộc chiến đấu tính gộp lại tạo thành X Điểm thiêu đốt tổn thương (PVP, PVE Chiến đấu đều tính, hảo hữu luận bàn không tính )
B6: Tính gộp lại chảy máu tổn thương | C6: Đơn cuộc chiến đấu tính gộp lại tạo thành X Điểm chảy máu tổn thương (PVP, PVE Chiến đấu đều tính, hảo hữu luận bàn không tính )
B7: Công hội Boss | C7: Công hội Boss Phó bản bên trong, đơn cuộc chiến đấu tính gộp lại tạo thành X Điểm thương tổn
B8: Phù văn thu thập | C8: Tính gộp lại thu hoạch được X Cái N Cấp phù văn
B14: Nhiệm vụ chính tuyến thiếu khuyết sự kiện loại hình
B15: Tàng Bảo Các | C15: Tàng Bảo Các bên trong hối đoái 1 Lần thương phẩm

Sheet Sheet1
A1: 457001 | B1: 4001 | C1: Nạp tiền nhiệm vụ | D1: Tính gộp lại nạp tiền 10000 Nguyên | G1: 10000 | J1: 4 | N1: 2 | P1: 2 | R1: 0:1:200#3:100002:50
A2: 457002 | B2: 4001 | C2: Nạp tiền nhiệm vụ | D2: Tính gộp lại nạp tiền 20000 Nguyên | G2: 20000 | J2: 4 | N2: 2 | P2: 2 | R2: 0:1:400#3:100022:3
A3: 457003 | B3: 4001 | C3: Nạp tiền nhiệm vụ | D3: Tính gộp lại nạp tiền 50000 Nguyên | G3: 50000 | J3: 4 | N3: 2 | P3: 2 | R3: 0:1:1000#3:100006:1
A4: 457004 | B4: 4001 | C4: Nạp tiền nhiệm vụ | D4: Tính gộp lại nạp tiền 100000 Nguyên | G4: 100000 | J4: 4 | N4: 2 | P4: 2 | R4: 0:1:2000#3:100025:1
A5: 457005 | B5: 4001 | C5: Nạp tiền nhiệm vụ | D5: Tính gộp lại nạp tiền 200000 Nguyên | G5: 200000 | J5: 4 | N5: 2 | P5: 2 | R5: 0:1:3000#3:100004:5000
A6: 457006 | B6: 4001 | C6: Nạp tiền nhiệm vụ | D6: Tính gộp lại nạp tiền 300000 Nguyên | G6: 300000 | J6: 4 | N6: 2 | P6: 2 | R6: 0:1:5000#3:400008:1
A7: 457007 | B7: 4001 | C7: Nạp tiền nhiệm vụ | D7: Tính gộp lại nạp tiền 500000 Nguyên | G7: 500000 | J7: 4 | N7: 2 | P7: 2 | R7: 0:1:8000#4:606002:50

Sheet Sheet4
