Workbook

Sheet 先知圣殿召唤类型
A1: 召唤类型 | B1: 名称（备注） | C1: 召唤花费 | D1: 分组配置 | E1: 额外奖励 | F1: 幸运召唤触发次数 | G1: 幸运分组
A2: 1 | B2: Người | C2: 3:100025:1 | D2: 15:3000#14:7000 | E2: 0:7:1#3:100024:30#0:8:1 | F2: 300 | G2: 155
A3: 2 | B3: Tiên | C3: 3:100025:1 | D3: 25:3000#24:7000 | E3: 0:7:1#3:100024:30#0:8:1 | F3: 300 | G3: 255
A4: 3 | B4: Yêu | C4: 3:100025:1 | D4: 35:3000#34:7000 | E4: 0:7:1#3:100024:30#0:8:1 | F4: 300 | G4: 355
A5: 4 | B5: Thần Ma | C5: 3:100025:1 | D5: 45:2500#44:7500 | E5: 0:7:1#3:100024:30#0:8:1 | F5: 300 | G5: 455

Sheet 先知圣殿召唤分组
A1: ID | B1: 奖励内容 | C1: 分组 | D1: 权重 | E1: 碎片类型 | F1: 是否5星整卡 | I1: 对照 | J1: 对照2 | K1: 阵营 | L1: 展示权重
A2: 1 | B2: 4:606003:30 | C2: 14 | D2: 2000 | E2: 1 | F2: 0 | G2: 606003 | H2: =VLOOKUP(G2,[1]基础物品!$A:$B,2,0) -> 4星人族碎片 | I2: =VLOOKUP(H2,[2]英雄召唤星组!$F:$I,3,0) -> #N/A | J2: 4 | K2: =VLOOKUP(H2,[3]英雄基础!$E:$F,2,0) -> #N/A | L2: 2000
A3: 2 | B3: 4:601013:30 | C3: 14 | D3: 2000 | E3: 0 | F3: 0 | G3: 601013 | H3: =VLOOKUP(G3,[1]基础物品!$A:$B,2,0) -> 申公豹 | I3: =VLOOKUP(H3,[2]英雄召唤星组!$F:$I,3,0) -> 75 | J3: =VLOOKUP(H3,[2]英雄召唤星组!$F:$G,2,0) -> 甘道夫 | K3: =VLOOKUP(H3,[3]英雄基础!$E:$F,2,0) -> #N/A | L3: 2000
A4: 3 | B4: 4:601009:30 | C4: 14 | D4: 2000 | E4: 0 | F4: 0 | G4: 601009 | H4: =VLOOKUP(G4,[1]基础物品!$A:$B,2,0) -> 黄飞虎 | I4: =VLOOKUP(H4,[2]英雄召唤星组!$F:$I,3,0) -> 75 | J4: =VLOOKUP(H4,[2]英雄召唤星组!$F:$G,2,0) -> 圣锤提尔 | K4: =VLOOKUP(H4,[3]英雄基础!$E:$F,2,0) -> #N/A | L4: 2000
A5: 4 | B5: 4:601011:30 | C5: 14 | D5: 2000 | E5: 0 | F5: 0 | G5: 601011 | H5: =VLOOKUP(G5,[1]基础物品!$A:$B,2,0) -> 采臣 | I5: =VLOOKUP(H5,[2]英雄召唤星组!$F:$I,3,0) -> 75 | J5: =VLOOKUP(H5,[2]英雄召唤星组!$F:$G,2,0) -> 吟游诗人 | K5: =VLOOKUP(H5,[3]英雄基础!$E:$F,2,0) -> #N/A | L5: 2000
A6: 5 | B6: 4:601012:30 | C6: 14 | D6: 2000 | E6: 0 | F6: 0 | G6: 601012 | H6: =VLOOKUP(G6,[1]基础物品!$A:$B,2,0) -> 纣王 | I6: =VLOOKUP(H6,[2]英雄召唤星组!$F:$I,3,0) -> 75 | J6: =VLOOKUP(H6,[2]英雄召唤星组!$F:$G,2,0) -> 亡灵收割者 | K6: =VLOOKUP(H6,[3]英雄基础!$E:$F,2,0) -> #N/A | L6: 2000
A7: 6 | B7: 4:606008:15 | C7: 15 | D7: 1500 | E7: 1 | F7: 0 | G7: 606008 | H7: =VLOOKUP(G7,[1]基础物品!$A:$B,2,0) -> 5星人族碎片 | I7: =VLOOKUP(H7,[2]英雄召唤星组!$F:$I,3,0) -> #N/A | J7: =VLOOKUP(H7,[2]英雄召唤星组!$F:$G,2,0) -> #N/A | K7: =VLOOKUP(H7,[3]英雄基础!$E:$F,2,0) -> #N/A | L7: 1500
A8: 7 | B8: 4:606008:20 | C8: 15 | D8: 1000 | E8: 1 | F8: 0 | G8: 606008 | H8: =VLOOKUP(G8,[1]基础物品!$A:$B,2,0) -> 5星人族碎片 | I8: =VLOOKUP(H8,[2]英雄召唤星组!$F:$I,3,0) -> #N/A | J8: =VLOOKUP(H8,[2]英雄召唤星组!$F:$G,2,0) -> #N/A | K8: =VLOOKUP(H8,[3]英雄基础!$E:$F,2,0) -> #N/A | L8: 1000
A9: 8 | B9: 4:606008:25 | C9: 15 | D9: 500 | E9: 1 | F9: 0 | G9: 606008 | H9: =VLOOKUP(G9,[1]基础物品!$A:$B,2,0) -> 5星人族碎片 | I9: =VLOOKUP(H9,[2]英雄召唤星组!$F:$I,3,0) -> #N/A | J9: =VLOOKUP(H9,[2]英雄召唤星组!$F:$G,2,0) -> #N/A | K9: =VLOOKUP(H9,[3]英雄基础!$E:$F,2,0) -> #N/A | L9: 500
A10: 9 | B10: 4:601015:50 | C10: 15 | D10: 593 | E10: 0 | F10: 1 | G10: 601015 | H10: =VLOOKUP(G10,[1]基础物品!$A:$B,2,0) -> 邓婵玉 | I10: =VLOOKUP(H10,[2]英雄召唤星组!$F:$I,3,0) -> 14 | J10: =VLOOKUP(H10,[2]英雄召唤星组!$F:$G,2,0) -> 凯兰崔尔 | K10: =VLOOKUP(H10,[3]英雄基础!$E:$F,2,0) -> #N/A | L10: 786
A11: 10 | B11: 4:601022:50 | C11: 15 | D11: 593 | E11: 0 | F11: 1 | G11: 601022 | H11: =VLOOKUP(G11,[1]基础物品!$A:$B,2,0) -> 雷震子 | I11: =VLOOKUP(H11,[2]英雄召唤星组!$F:$I,3,0) -> 15 | J11: =VLOOKUP(H11,[2]英雄召唤星组!$F:$G,2,0) -> 美杜莎 | K11: =VLOOKUP(H11,[3]英雄基础!$E:$F,2,0) -> #N/A | L11: 400
A12: 11 | B12: 4:601014:50 | C12: 15 | D12: 400 | E12: 0 | F12: 1 | G12: 601014 | H12: =VLOOKUP(G12,[1]基础物品!$A:$B,2,0) -> 李靖 | I12: =VLOOKUP(H12,[2]英雄召唤星组!$F:$I,3,0) -> 5 | J12: =VLOOKUP(H12,[2]英雄召唤星组!$F:$G,2,0) -> 奥丁 | K12: =VLOOKUP(H12,[3]英雄基础!$E:$F,2,0) -> #N/A | L12: 300
A13: 12 | B13: 4:601016:50 | C13: 15 | D13: 70 | E13: 0 | F13: 1 | G13: 601016 | H13: =VLOOKUP(G13,[1]基础物品!$A:$B,2,0) -> 嫦娥 | I13: =VLOOKUP(H13,[2]英雄召唤星组!$F:$I,3,0) -> 2 | J13: =VLOOKUP(H13,[2]英雄召唤星组!$F:$G,2,0) -> 潘 | K13: =VLOOKUP(H13,[3]英雄基础!$E:$F,2,0) -> #N/A | L13: 300
A14: 13 | B14: 4:601018:50 | C14: 15 | D14: 450 | E14: 0 | F14: 1 | G14: 601018 | H14: =VLOOKUP(G14,[1]基础物品!$A:$B,2,0) -> 姬发 | I14: =VLOOKUP(H14,[2]英雄召唤星组!$F:$I,3,0) -> 5 | J14: =VLOOKUP(H14,[2]英雄召唤星组!$F:$G,2,0) -> 魅魔女王 | K14: =VLOOKUP(H14,[3]英雄基础!$E:$F,2,0) -> #N/A | L14: 400
... A33: 32 | B33: 4:602015:50 | C33: 25 | D33: 317 | E33: 0 | F33: 1 | G33: 602015 | H33: =VLOOKUP(G33,[1]基础物品!$A:$B,2,0) -> 卷帘大将 | I33: =VLOOKUP(H33,[2]英雄召唤星组!$F:$I,3,0) -> 6 | J33: =VLOOKUP(H33,[2]英雄召唤星组!$F:$G,2,0) -> 泰坦 | K33: =VLOOKUP(H33,[3]英雄基础!$E:$F,2,0) -> #N/A | L33: 348
A34: 33 | B34: 4:602024:50 | C34: 25 | D34: 250 | E34: 0 | F34: 1 | G34: 602024 | H34: =VLOOKUP(G34,[4]基础物品!$A:$B,2,0) -> 玄奘 | I34: =VLOOKUP(H34,[2]英雄召唤星组!$F:$I,3,0) -> 6 | J34: =VLOOKUP(H34,[2]英雄召唤星组!$F:$G,2,0) -> 利维坦 | K34: =VLOOKUP(H34,[3]英雄基础!$E:$F,2,0) -> #N/A | L34: 160
A35: 34 | B35: 4:602025:50 | C35: 25 | D35: 250 | E35: 0 | F35: 1 | G35: 602025 | H35: =VLOOKUP(G35,[4]基础物品!$A:$B,2,0) -> 白龙 | I35: =VLOOKUP(H35,[2]英雄召唤星组!$F:$I,3,0) -> 6 | J35: =VLOOKUP(H35,[2]英雄召唤星组!$F:$G,2,0) -> 原创英雄 | K35: =VLOOKUP(H35,[3]英雄基础!$E:$F,2,0) -> #N/A | L35: 160
A36: 35 | B36: 4:606005:30 | C36: 34 | D36: 2000 | E36: 1 | F36: 0 | G36: 606005 | H36: =VLOOKUP(G36,[1]基础物品!$A:$B,2,0) -> 4星妖族碎片 | I36: =VLOOKUP(H36,[2]英雄召唤星组!$F:$I,3,0) -> #N/A | J36: =VLOOKUP(H36,[2]英雄召唤星组!$F:$G,2,0) -> #N/A | K36: =VLOOKUP(H36,[3]英雄基础!$E:$F,2,0) -> #N/A | L36: 2000
A37: 36 | B37: 4:603010:30 | C37: 34 | D37: 2000 | E37: 0 | F37: 0 | G37: 603010 | H37: =VLOOKUP(G37,[1]基础物品!$A:$B,2,0) -> 鬼将 | I37: =VLOOKUP(H37,[2]英雄召唤星组!$F:$I,3,0) -> 75 | J37: =VLOOKUP(H37,[2]英雄召唤星组!$F:$G,2,0) -> 阿伽门农 | K37: =VLOOKUP(H37,[3]英雄基础!$E:$F,2,0) -> #N/A | L37: 2000
A38: 37 | B38: 4:603012:30 | C38: 34 | D38: 2000 | E38: 0 | F38: 0 | G38: 603012 | H38: =VLOOKUP(G38,[1]基础物品!$A:$B,2,0) -> 盘丝 | I38: =VLOOKUP(H38,[2]英雄召唤星组!$F:$I,3,0) -> 75 | J38: =VLOOKUP(H38,[2]英雄召唤星组!$F:$G,2,0) -> 凯瑟琳 | K38: =VLOOKUP(H38,[3]英雄基础!$E:$F,2,0) -> #N/A | L38: 2000
A39: 38 | B39: 4:606010:15 | C39: 35 | D39: 1500 | E39: 1 | F39: 0 | G39: 606010 | H39: =VLOOKUP(G39,[1]基础物品!$A:$B,2,0) -> 5星妖族碎片 | I39: =VLOOKUP(H39,[2]英雄召唤星组!$F:$I,3,0) -> #N/A | J39: =VLOOKUP(H39,[2]英雄召唤星组!$F:$G,2,0) -> #N/A | K39: =VLOOKUP(H39,[3]英雄基础!$E:$F,2,0) -> #N/A | L39: 1500
A40: 39 | B40: 4:606010:20 | C40: 35 | D40: 1000 | E40: 1 | F40: 0 | G40: 606010 | H40: =VLOOKUP(G40,[1]基础物品!$A:$B,2,0) -> 5星妖族碎片 | I40: =VLOOKUP(H40,[2]英雄召唤星组!$F:$I,3,0) -> #N/A | J40: =VLOOKUP(H40,[2]英雄召唤星组!$F:$G,2,0) -> #N/A | K40: =VLOOKUP(H40,[3]英雄基础!$E:$F,2,0) -> #N/A | L40: 1000
A41: 40 | B41: 4:606010:25 | C41: 35 | D41: 500 | E41: 1 | F41: 0 | G41: 606010 | H41: =VLOOKUP(G41,[1]基础物品!$A:$B,2,0) -> 5星妖族碎片 | I41: =VLOOKUP(H41,[2]英雄召唤星组!$F:$I,3,0) -> #N/A | J41: =VLOOKUP(H41,[2]英雄召唤星组!$F:$G,2,0) -> #N/A | K41: =VLOOKUP(H41,[3]英雄基础!$E:$F,2,0) -> #N/A | L41: 500
A42: 41 | B42: 4:603019:50 | C42: 35 | D42: 813 | E42: 0 | F42: 1 | G42: 603019 | H42: =VLOOKUP(G42,[1]基础物品!$A:$B,2,0) -> 金乌 | I42: =VLOOKUP(H42,[2]英雄召唤星组!$F:$I,3,0) -> 14 | J42: =VLOOKUP(H42,[2]英雄召唤星组!$F:$G,2,0) -> 吸血伯爵 | K42: =VLOOKUP(H42,[3]英雄基础!$E:$F,2,0) -> #N/A | L42: 833
A43: 42 | B43: 4:603018:50 | C43: 35 | D43: 813 | E43: 0 | F43: 1 | G43: 603018 | H43: =VLOOKUP(G43,[1]基础物品!$A:$B,2,0) -> 擎苍 | I43: =VLOOKUP(H43,[2]英雄召唤星组!$F:$I,3,0) -> 14 | J43: =VLOOKUP(H43,[2]英雄召唤星组!$F:$G,2,0) -> 剑豪卡赞 | K43: =VLOOKUP(H43,[3]英雄基础!$E:$F,2,0) -> #N/A | L43: 833
A44: 43 | B44: 4:603014:50 | C44: 35 | D44: 200 | E44: 0 | F44: 1 | G44: 603014 | H44: =VLOOKUP(G44,[1]基础物品!$A:$B,2,0) -> 红孩儿 | I44: =VLOOKUP(H44,[2]英雄召唤星组!$F:$I,3,0) -> 6 | J44: =VLOOKUP(H44,[2]英雄召唤星组!$F:$G,2,0) -> 菲尼克斯 | K44: =VLOOKUP(H44,[3]英雄基础!$E:$F,2,0) -> #N/A | L44: 249
A45: 44 | B45: 4:603021:50 | C45: 35 | D45: 80 | E45: 0 | F45: 1 | G45: 603021 | H45: =VLOOKUP(G45,[1]基础物品!$A:$B,2,0) -> 白骨夫人 | I45: =VLOOKUP(H45,[2]英雄召唤星组!$F:$I,3,0) -> 14 | J45: =VLOOKUP(H45,[2]英雄召唤星组!$F:$G,2,0) -> 炎魔之王 | K45: =VLOOKUP(H45,[3]英雄基础!$E:$F,2,0) -> #N/A | L45: 287
A46: 45 | B46: 4:603022:50 | C46: 35 | D46: 215 | E46: 0 | F46: 1 | G46: 603022 | H46: =VLOOKUP(G46,[1]基础物品!$A:$B,2,0) -> 妲己 | I46: =VLOOKUP(H46,[2]英雄召唤星组!$F:$I,3,0) -> 6 | J46: =VLOOKUP(H46,[2]英雄召唤星组!$F:$G,2,0) -> 阿波罗 | K46: =VLOOKUP(H46,[3]英雄基础!$E:$F,2,0) -> #N/A | L46: 287
A47: 46 | B47: 4:603015:50 | C47: 35 | D47: 215 | E47: 0 | F47: 1 | G47: 603015 | H47: =VLOOKUP(G47,[1]基础物品!$A:$B,2,0) -> 石矶 | I47: =VLOOKUP(H47,[2]英雄召唤星组!$F:$I,3,0) -> 6 | J47: =VLOOKUP(H47,[2]英雄召唤星组!$F:$G,2,0) -> 普罗米修斯 | K47: =VLOOKUP(H47,[3]英雄基础!$E:$F,2,0) -> #N/A | L47: 140
... A50: 49 | B50: 4:603017:50 | C50: 35 | D50: 500 | E50: 0 | F50: 1 | G50: 603017 | H50: =VLOOKUP(G50,[1]基础物品!$A:$B,2,0) -> 牛魔王 | I50: =VLOOKUP(H50,[2]英雄召唤星组!$F:$I,3,0) -> 14 | J50: =VLOOKUP(H50,[2]英雄召唤星组!$F:$G,2,0) -> 炽天使 | K50: =VLOOKUP(H50,[3]英雄基础!$E:$F,2,0) -> #N/A | L50: 287
A51: 50 | B51: 4:603023:50 | C51: 35 | D51: 60 | E51: 0 | F51: 1 | G51: 603023 | H51: 孔宣 | I51: =VLOOKUP(H51,[2]英雄召唤星组!$F:$I,3,0) -> 1 | J51: =VLOOKUP(H51,[2]英雄召唤星组!$F:$G,2,0) -> 阿波罗 | K51: =VLOOKUP(H51,[3]英雄基础!$E:$F,2,0) -> #N/A | L51: 100
A52: 51 | B52: 4:603024:50 | C52: 35 | D52: 20 | E52: 0 | F52: 1 | G52: 603024 | H52: 曼珠 | I52: 1 | J52: =VLOOKUP(H52,[2]英雄召唤星组!$F:$G,2,0) -> 原创英雄 | K52: =VLOOKUP(H52,[3]英雄基础!$E:$F,2,0) -> #N/A | L52: 41
A53: 52 | B53: 4:606006:15 | C53: 44 | D53: 2660 | E53: 1 | F53: 0 | G53: 606006 | H53: =VLOOKUP(G53,[1]基础物品!$A:$B,2,0) -> 4星神族碎片 | I53: =VLOOKUP(H53,[2]英雄召唤星组!$F:$I,3,0) -> #N/A | J53: =VLOOKUP(H53,[2]英雄召唤星组!$F:$G,2,0) -> #N/A | K53: =VLOOKUP(H53,[3]英雄基础!$E:$F,2,0) -> #N/A | L53: 2660
A54: 53 | B54: 4:606006:30 | C54: 44 | D54: 2660 | E54: 1 | F54: 0 | G54: 606006 | H54: =VLOOKUP(G54,[1]基础物品!$A:$B,2,0) -> 4星神族碎片 | I54: =VLOOKUP(H54,[2]英雄召唤星组!$F:$I,3,0) -> #N/A | J54: =VLOOKUP(H54,[2]英雄召唤星组!$F:$G,2,0) -> #N/A | K54: =VLOOKUP(H54,[3]英雄基础!$E:$F,2,0) -> #N/A | L54: 2660
A55: 54 | B55: 4:606007:15 | C55: 44 | D55: 2660 | E55: 1 | F55: 0 | G55: 606007 | H55: =VLOOKUP(G55,[1]基础物品!$A:$B,2,0) -> 4星魔族碎片 | I55: =VLOOKUP(H55,[2]英雄召唤星组!$F:$I,3,0) -> #N/A | J55: =VLOOKUP(H55,[2]英雄召唤星组!$F:$G,2,0) -> #N/A | K55: =VLOOKUP(H55,[3]英雄基础!$E:$F,2,0) -> #N/A | L55: 2660
A56: 55 | B56: 4:606007:30 | C56: 44 | D56: 2660 | E56: 1 | F56: 0 | G56: 606007 | H56: =VLOOKUP(G56,[1]基础物品!$A:$B,2,0) -> 4星魔族碎片 | I56: =VLOOKUP(H56,[2]英雄召唤星组!$F:$I,3,0) -> #N/A | J56: =VLOOKUP(H56,[2]英雄召唤星组!$F:$G,2,0) -> #N/A | K56: =VLOOKUP(H56,[3]英雄基础!$E:$F,2,0) -> #N/A | L56: 2660
A57: 56 | B57: 4:604003:30 | C57: 44 | D57: 585 | E57: 0 | F57: 0 | G57: 604003 | H57: =VLOOKUP(G57,[1]基础物品!$A:$B,2,0) -> 女魃 | I57: =VLOOKUP(H57,[2]英雄召唤星组!$F:$I,3,0) -> 25 | J57: =VLOOKUP(H57,[2]英雄召唤星组!$F:$G,2,0) -> 月之祭祀 | K57: =VLOOKUP(H57,[3]英雄基础!$E:$F,2,0) -> #N/A | L57: 585
A58: 57 | B58: 4:604004:30 | C58: 44 | D58: 585 | E58: 0 | F58: 0 | G58: 604004 | H58: =VLOOKUP(G58,[1]基础物品!$A:$B,2,0) -> 监兵 | I58: =VLOOKUP(H58,[2]英雄召唤星组!$F:$I,3,0) -> 25 | J58: =VLOOKUP(H58,[2]英雄召唤星组!$F:$G,2,0) -> 精灵王子 | K58: =VLOOKUP(H58,[3]英雄基础!$E:$F,2,0) -> #N/A | L58: 585
A59: 58 | B59: 4:604005:30 | C59: 44 | D59: 585 | E59: 0 | F59: 0 | G59: 604005 | H59: =VLOOKUP(G59,[1]基础物品!$A:$B,2,0) -> 洛神 | I59: =VLOOKUP(H59,[2]英雄召唤星组!$F:$I,3,0) -> 25 | J59: =VLOOKUP(H59,[2]英雄召唤星组!$F:$G,2,0) -> 丘比特 | K59: =VLOOKUP(H59,[3]英雄基础!$E:$F,2,0) -> #N/A | L59: 585
A60: 59 | B60: 4:605003:30 | C60: 44 | D60: 585 | E60: 0 | F60: 0 | G60: 605003 | H60: =VLOOKUP(G60,[1]基础物品!$A:$B,2,0) -> 破军 | I60: =VLOOKUP(H60,[2]英雄召唤星组!$F:$I,3,0) -> 25 | J60: =VLOOKUP(H60,[2]英雄召唤星组!$F:$G,2,0) -> 阿克琉斯 | K60: =VLOOKUP(H60,[3]英雄基础!$E:$F,2,0) -> #N/A | L60: 585
...

Sheet 英雄转换
A1: ID | B1: 星级 | C1: 转换耗费
A2: 1 | B2: 4 | C2: 3:100024:20
A3: 2 | B3: 5 | C3: 3:100024:100

Sheet 英雄转换分组
A1: ID | B1: 英雄ID | C1: 分组 | D1: 权重 | E1: 备注 | G1: 对照 | H1: 原版 | I1: 更改 | J1: 新权重
A2: 1 | B2: 101101 | C2: 1 | D2: 2000 | E2: 4星人族 | F2: =VLOOKUP(B2,[3]英雄基础!$A:$F,6,0) -> 采臣 | G2: =VLOOKUP(F2,[2]英雄召唤星组!$F:$H,3,0) -> 75
A3: 2 | B3: 100901 | C3: 1 | D3: 2000 | E3: 4星人族 | F3: =VLOOKUP(B3,[3]英雄基础!$A:$F,6,0) -> 黄飞虎 | G3: =VLOOKUP(F3,[2]英雄召唤星组!$F:$H,3,0) -> 75
A4: 3 | B4: 101301 | C4: 1 | D4: 2000 | E4: 4星人族 | F4: =VLOOKUP(B4,[3]英雄基础!$A:$F,6,0) -> 申公豹 | G4: =VLOOKUP(F4,[2]英雄召唤星组!$F:$H,3,0) -> 75
A5: 4 | B5: 101201 | C5: 1 | D5: 2000 | E5: 4星人族 | F5: =VLOOKUP(B5,[3]英雄基础!$A:$F,6,0) -> 纣王 | G5: =VLOOKUP(F5,[2]英雄召唤星组!$F:$H,3,0) -> 75
A6: 5 | B6: 101401 | C6: 2 | D6: 500 | E6: 5星人族 | F6: =VLOOKUP(B6,[3]英雄基础!$A:$F,6,0) -> 李靖 | G6: =VLOOKUP(F6,[2]英雄召唤星组!$F:$H,3,0) -> 5 | H6: =D6/SUM($D$6:$D$14) -> 0.11627907 | I6: =G6/SUM($G$6:$G$14) -> 0.11627907 | J6: =G6*100 -> 500
A7: 6 | B7: 101601 | C7: 2 | D7: 300 | E7: 5星人族 | F7: =VLOOKUP(B7,[3]英雄基础!$A:$F,6,0) -> 嫦娥 | G7: 3 | H7: =D7/SUM($D$6:$D$14) -> 0.069767442 | I7: =G7/SUM($G$6:$G$14) -> 0.069767442 | J7: =G7*100 -> 300
A8: 7 | B8: 102201 | C8: 2 | D8: 1000 | E8: 5星人族 | F8: =VLOOKUP(B8,[3]英雄基础!$A:$F,6,0) -> 雷震子 | G8: 10 | H8: =D8/SUM($D$6:$D$14) -> 0.23255814 | I8: =G8/SUM($G$6:$G$14) -> 0.23255814 | J8: =G8*100 -> 1000
A9: 8 | B9: 101501 | C9: 2 | D9: 1000 | E9: 5星人族 | F9: =VLOOKUP(B9,[3]英雄基础!$A:$F,6,0) -> 邓婵玉 | G9: 10 | H9: =D9/SUM($D$6:$D$14) -> 0.23255814 | I9: =G9/SUM($G$6:$G$14) -> 0.23255814 | J9: =G9*100 -> 1000
A10: 9 | B10: 101801 | C10: 2 | D10: 700 | E10: 5星人族 | F10: =VLOOKUP(B10,[3]英雄基础!$A:$F,6,0) -> 姬发 | G10: 7 | H10: =D10/SUM($D$6:$D$14) -> 0.1627907 | I10: =G10/SUM($G$6:$G$14) -> 0.1627907 | J10: =G10*100 -> 700
A11: 10 | B11: 102001 | C11: 2 | D11: 200 | E11: 5星人族 | F11: =VLOOKUP(B11,[3]英雄基础!$A:$F,6,0) -> 哪吒 | G11: 2 | H11: =D11/SUM($D$6:$D$14) -> 0.046511628 | I11: =G11/SUM($G$6:$G$14) -> 0.046511628 | J11: =G11*100 -> 200
A12: 11 | B12: 101701 | C12: 2 | D12: 200 | E12: 5星人族 | F12: =VLOOKUP(B12,[3]英雄基础!$A:$F,6,0) -> 后羿 | G12: 2 | H12: =D12/SUM($D$6:$D$14) -> 0.046511628 | I12: =G12/SUM($G$6:$G$14) -> 0.046511628 | J12: =G12*100 -> 200
A13: 12 | B13: 102101 | C13: 2 | D13: 200 | E13: 5星人族 | F13: =VLOOKUP(B13,[3]英雄基础!$A:$F,6,0) -> 姜子牙 | G13: 2 | H13: =D13/SUM($D$6:$D$14) -> 0.046511628 | I13: =G13/SUM($G$6:$G$14) -> 0.046511628 | J13: =G13*100 -> 200
A14: 13 | B14: 102301 | C14: 2 | D14: 200 | E14: 5星人族 | F14: =VLOOKUP(B14,[3]英雄基础!$A:$F,6,0) -> 花木兰 | G14: 2 | H14: =D14/SUM($D$6:$D$14) -> 0.046511628 | I14: =G14/SUM($G$6:$G$14) -> 0.046511628 | J14: =G14*100 -> 200 | K14: =J14/SUM(J6:J14) -> 0.046511628
A15: 14 | B15: 200901 | C15: 3 | D15: 2000 | E15: 4星仙族 | F15: =VLOOKUP(B15,[3]英雄基础!$A:$F,6,0) -> 太白金星 | G15: =VLOOKUP(F15,[2]英雄召唤星组!$F:$H,3,0) -> 75
A16: 15 | B16: 201101 | C16: 3 | D16: 2000 | E16: 4星仙族 | F16: =VLOOKUP(B16,[3]英雄基础!$A:$F,6,0) -> 织女 | G16: =VLOOKUP(F16,[2]英雄召唤星组!$F:$H,3,0) -> 75
A17: 16 | B17: 201301 | C17: 3 | D17: 2000 | E17: 4星仙族 | F17: =VLOOKUP(B17,[3]英雄基础!$A:$F,6,0) -> 雨师 | G17: =VLOOKUP(F17,[2]英雄召唤星组!$F:$H,3,0) -> 100
A18: 17 | B18: 201601 | C18: 4 | D18: 1500 | E18: 5星仙族 | F18: =VLOOKUP(B18,[3]英雄基础!$A:$F,6,0) -> 南极仙子 | G18: 15 | H18: =D18/SUM($D$18:$D$27) -> 0.17647059 | I18: =G18/SUM($G$18:$G$27) -> 0.17647059 | J18: =G18*100 -> 1500
A19: 18 | B19: 201701 | C19: 4 | D19: 600 | E19: 5星仙族 | F19: =VLOOKUP(B19,[3]英雄基础!$A:$F,6,0) -> 禄缘上仙 | G19: =VLOOKUP(F19,[2]英雄召唤星组!$F:$H,3,0) -> 6 | H19: =D19/SUM($D$18:$D$27) -> 0.070588235 | I19: =G19/SUM($G$18:$G$27) -> 0.070588235 | J19: =G19*100 -> 600
A20: 19 | B20: 201401 | C20: 4 | D20: 1400 | E20: 5星仙族 | F20: =VLOOKUP(B20,[3]英雄基础!$A:$F,6,0) -> 天蓬元帅 | G20: =VLOOKUP(F20,[2]英雄召唤星组!$F:$H,3,0) -> 14 | H20: =D20/SUM($D$18:$D$27) -> 0.16470588 | I20: =G20/SUM($G$18:$G$27) -> 0.16470588 | J20: =G20*100 -> 1400
A21: 20 | B21: 202001 | C21: 4 | D21: 700 | E21: 5星仙族 | F21: =VLOOKUP(B21,[3]英雄基础!$A:$F,6,0) -> 通天教主 | G21: 7 | H21: =D21/SUM($D$18:$D$27) -> 0.082352941 | I21: =G21/SUM($G$18:$G$27) -> 0.082352941 | J21: =G21*100 -> 700
A22: 21 | B22: 201501 | C22: 4 | D22: 700 | E22: 5星仙族 | F22: =VLOOKUP(B22,[3]英雄基础!$A:$F,6,0) -> 卷帘大将 | G22: 7 | H22: =D22/SUM($D$18:$D$27) -> 0.082352941 | I22: =G22/SUM($G$18:$G$27) -> 0.082352941 | J22: =G22*100 -> 700
A23: 22 | B23: 201801 | C23: 4 | D23: 500 | E23: 5星仙族 | F23: =VLOOKUP(B23,[3]英雄基础!$A:$F,6,0) -> 斗战胜佛 | G23: 5 | H23: =D23/SUM($D$18:$D$27) -> 0.058823529 | I23: =G23/SUM($G$18:$G$27) -> 0.058823529 | J23: =G23*100 -> 500
A24: 23 | B24: 202101 | C24: 4 | D24: 700 | E24: 5星仙族 | F24: =VLOOKUP(B24,[3]英雄基础!$A:$F,6,0) -> 元始天尊 | G24: 7 | H24: =D24/SUM($D$18:$D$27) -> 0.082352941 | I24: =G24/SUM($G$18:$G$27) -> 0.082352941 | J24: =G24*100 -> 700
A25: 24 | B25: 202201 | C25: 4 | D25: 1500 | E25: 5星仙族 | F25: =VLOOKUP(B25,[3]英雄基础!$A:$F,6,0) -> 云中子 | G25: =VLOOKUP(F25,[2]英雄召唤星组!$F:$H,3,0) -> 15 | H25: =D25/SUM($D$18:$D$27) -> 0.17647059 | I25: =G25/SUM($G$18:$G$27) -> 0.17647059 | J25: =G25*100 -> 1500
A26: 25 | B26: 202301 | C26: 4 | D26: 300 | E26: 5星仙族 | F26: =VLOOKUP(B26,[3]英雄基础!$A:$F,6,0) -> 白龙 | G26: 3 | H26: =D26/SUM($D$18:$D$27) -> 0.035294118 | I26: =G26/SUM($G$18:$G$27) -> 0.035294118 | J26: =G26*100 -> 300
A27: 26 | B27: 202401 | C27: 4 | D27: 600 | E27: 5星仙族 | F27: =VLOOKUP(B27,[3]英雄基础!$A:$F,6,0) -> 玄奘 | G27: =VLOOKUP(F27,[2]英雄召唤星组!$F:$H,3,0) -> 6 | H27: =D27/SUM($D$18:$D$27) -> 0.070588235 | I27: =G27/SUM($G$18:$G$27) -> 0.070588235 | J27: =G27*100 -> 600
A28: 27 | B28: 301101 | C28: 5 | D28: 2000 | E28: 4星妖族 | F28: =VLOOKUP(B28,[3]英雄基础!$A:$F,6,0) -> 金角大王 | G28: =VLOOKUP(F28,[2]英雄召唤星组!$F:$H,3,0) -> 75
A29: 28 | B29: 301001 | C29: 5 | D29: 2000 | E29: 4星妖族 | F29: =VLOOKUP(B29,[3]英雄基础!$A:$F,6,0) -> 鬼将 | G29: =VLOOKUP(F29,[2]英雄召唤星组!$F:$H,3,0) -> 75
A30: 29 | B30: 301201 | C30: 5 | D30: 2000 | E30: 4星妖族 | F30: =VLOOKUP(B30,[3]英雄基础!$A:$F,6,0) -> 盘丝 | G30: =VLOOKUP(F30,[2]英雄召唤星组!$F:$H,3,0) -> 75
A31: 30 | B31: 301501 | C31: 6 | D31: 800 | E31: 5星妖族 | F31: =VLOOKUP(B31,[3]英雄基础!$A:$F,6,0) -> 石矶 | G31: 8 | H31: =D31/SUM($D$31:$D$41) -> 0.095238095 | I31: =G31/SUM($G$31:$G$41) -> 0.095238095 | J31: =G31*100 -> 800
A32: 31 | B32: 301601 | C32: 6 | D32: 200 | E32: 5星妖族 | F32: =VLOOKUP(B32,[3]英雄基础!$A:$F,6,0) -> 混天大圣 | G32: =VLOOKUP(F32,[2]英雄召唤星组!$F:$H,3,0) -> 2 | H32: =D32/SUM($D$31:$D$41) -> 0.023809524 | I32: =G32/SUM($G$31:$G$41) -> 0.023809524 | J32: =G32*100 -> 200
A33: 32 | B33: 301401 | C33: 6 | D33: 200 | E33: 5星妖族 | F33: =VLOOKUP(B33,[3]英雄基础!$A:$F,6,0) -> 红孩儿 | G33: 2 | H33: =D33/SUM($D$31:$D$41) -> 0.023809524 | I33: =G33/SUM($G$31:$G$41) -> 0.023809524 | J33: =G33*100 -> 200
A34: 33 | B34: 301901 | C34: 6 | D34: 1600 | E34: 5星妖族 | F34: =VLOOKUP(B34,[3]英雄基础!$A:$F,6,0) -> 金乌 | G34: 16 | H34: =D34/SUM($D$31:$D$41) -> 0.19047619 | I34: =G34/SUM($G$31:$G$41) -> 0.19047619 | J34: =G34*100 -> 1600
A35: 34 | B35: 302101 | C35: 6 | D35: 1000 | E35: 5星妖族 | F35: =VLOOKUP(B35,[3]英雄基础!$A:$F,6,0) -> 白骨夫人 | G35: 10 | H35: =D35/SUM($D$31:$D$41) -> 0.11904762 | I35: =G35/SUM($G$31:$G$41) -> 0.11904762 | J35: =G35*100 -> 1000
A36: 35 | B36: 302201 | C36: 6 | D36: 500 | E36: 5星妖族 | F36: =VLOOKUP(B36,[3]英雄基础!$A:$F,6,0) -> 妲己 | G36: 5 | H36: =D36/SUM($D$31:$D$41) -> 0.05952381 | I36: =G36/SUM($G$31:$G$41) -> 0.05952381 | J36: =G36*100 -> 500
A37: 36 | B37: 301701 | C37: 6 | D37: 1400 | E37: 5星妖族 | F37: =VLOOKUP(B37,[3]英雄基础!$A:$F,6,0) -> 牛魔王 | G37: 14 | H37: =D37/SUM($D$31:$D$41) -> 0.16666667 | I37: =G37/SUM($G$31:$G$41) -> 0.16666667 | J37: =G37*100 -> 1400
A38: 37 | B38: 301801 | C38: 6 | D38: 1500 | E38: 5星妖族 | F38: =VLOOKUP(B38,[3]英雄基础!$A:$F,6,0) -> 擎苍 | G38: 15 | H38: =D38/SUM($D$31:$D$41) -> 0.17857143 | I38: =G38/SUM($G$31:$G$41) -> 0.17857143 | J38: =G38*100 -> 1500
A39: 38 | B39: 302001 | C39: 6 | D39: 600 | E39: 5星妖族 | F39: =VLOOKUP(B39,[3]英雄基础!$A:$F,6,0) -> 敖丙 | G39: 6 | H39: =D39/SUM($D$31:$D$41) -> 0.071428571 | I39: =G39/SUM($G$31:$G$41) -> 0.071428571 | J39: =G39*100 -> 600
A40: 39 | B40: 302301 | C40: 6 | D40: 400 | E40: 5星妖族 | F40: =VLOOKUP(B40,[3]英雄基础!$A:$F,6,0) -> 孔宣 | G40: 4 | H40: =D40/SUM($D$31:$D$41) -> 0.047619048 | I40: =G40/SUM($G$31:$G$41) -> 0.047619048 | J40: =G40*100 -> 400
...
