Workbook

Sheet 公会宝库商品
A1: 商品ID | B1: 商品内容 | C1: 出售价格 | D1: 放入奖励 | E1: 过期天数 | F1: 每日限购 | G1: 库存上限 | H1: 页签类型 | I1: 玩家可放入的商品 | J1: 是否超值
A2: 1001 | B2: 3:100001:100 | C2: 500 | D2: 100 | E2: 999 | F2: -1 | G2: 9999 | H2: 2 | I2: 1 | J2: 0 | K2: 进阶石
A3: 1002 | B3: 3:100001:100 | C3: 400 | D3: 100 | E3: 999 | F3: -1 | G3: 9999 | H3: 2 | I3: 1 | J3: 1 | K3: 进阶石
A4: 1003 | B4: 3:100002:100 | C4: 10000 | D4: 2000 | E4: 999 | F4: -1 | G4: 9999 | H4: 2 | I4: 1 | J4: 0 | K4: 太乙精金
A5: 1004 | B5: 3:100002:100 | C5: 8000 | D5: 2000 | E5: 999 | F5: -1 | G5: 9999 | H5: 2 | I5: 1 | J5: 1 | K5: 太乙精金
A6: 1005 | B6: 3:100005:1 | C6: 150 | D6: 30 | E6: 999 | F6: -1 | G6: 9999 | H6: 2 | I6: 1 | J6: 0 | K6: 普通寻宝券
A7: 1006 | B7: 3:100005:1 | C7: 120 | D7: 30 | E7: 999 | F7: -1 | G7: 9999 | H7: 2 | I7: 1 | J7: 1 | K7: 普通寻宝券
A8: 1007 | B8: 3:100006:1 | C8: 1000 | D8: 250 | E8: 999 | F8: -1 | G8: 9999 | H8: 2 | I8: 1 | J8: 0 | K8: 高级寻宝券
A9: 1008 | B9: 3:100006:1 | C9: 800 | D9: 200 | E9: 999 | F9: -1 | G9: 9999 | H9: 2 | I9: 1 | J9: 1 | K9: 高级寻宝券
A10: 1009 | B10: 3:100008:1 | C10: 650 | D10: 100 | E10: 999 | F10: -1 | G10: 9999 | H10: 2 | I10: 1 | J10: 0 | K10: 碧玉髓
A11: 1010 | B11: 3:100008:1 | C11: 520 | D11: 100 | E11: 999 | F11: -1 | G11: 9999 | H11: 2 | I11: 1 | J11: 1 | K11: 碧玉髓
A12: 1011 | B12: 3:100021:1 | C12: 100 | D12: 20 | E12: 999 | F12: -1 | G12: 9999 | H12: 2 | I12: 1 | J12: 0 | K12: 普通点将券
A13: 1012 | B13: 3:100021:1 | C13: 80 | D13: 20 | E13: 999 | F13: -1 | G13: 9999 | H13: 2 | I13: 1 | J13: 1 | K13: 普通点将券
... A101: 1100 | B101: 2:19000408:1 | C101: 2025 | D101: 405 | E101: 999 | F101: -1 | G101: 9999 | H101: 1 | I101: 1 | J101: 0 | K101: 装备
A102: 1101 | B102: 3:100224:10 | C102: 1000 | D102: 250 | E102: 999 | F102: -1 | G102: 9999 | H102: 2 | I102: 1 | J102: 1 | K102: 道具 | L102: 修为丹
A103: 1102 | B103: 3:100225:10 | C103: 2000 | D103: 500 | E103: 999 | F103: -1 | G103: 9999 | H103: 2 | I103: 1 | J103: 1 | K103: 道具 | L103: 秘笈
A104: 1103 | B104: 3:200018:1000 | C104: 500 | D104: 100 | E104: 999 | F104: -1 | G104: 9999 | H104: 2 | I104: 1 | J104: 0 | K104: 道具
A105: 2000 | B105: 4:601023:1 | C105: 1000 | D105: 500 | E105: 999 | F105: -1 | G105: 9999 | H105: 3 | I105: 1 | J105: 0 | K105: 花木兰
A106: 2001 | B106: 4:602024:1 | C106: 500 | D106: 250 | E106: 999 | F106: -1 | G106: 9999 | H106: 3 | I106: 1 | J106: 0 | K106: 玄奘
A107: 2002 | B107: 4:602026:1 | C107: 1500 | D107: 750 | E107: 999 | F107: -1 | G107: 9999 | H107: 3 | I107: 1 | J107: 0 | K107: 土地
A108: 2003 | B108: 4:602025:1 | C108: 500 | D108: 250 | E108: 999 | F108: -1 | G108: 9999 | H108: 3 | I108: 1 | J108: 0 | K108: 白龙
A109: 2004 | B109: 4:603024:1 | C109: 1000 | D109: 500 | E109: 999 | F109: -1 | G109: 9999 | H109: 3 | I109: 1 | J109: 0 | K109: 曼珠
A110: 2005 | B110: 4:603023:1 | C110: 1000 | D110: 500 | E110: 999 | F110: -1 | G110: 9999 | H110: 3 | I110: 1 | J110: 0 | K110: 孔宣

Sheet 公会宝库系统赠送奖励
A1: ID | B1: 商品ID | C1: 数量
A2: 1 | B2: 1002 | C2: 50 | D2: =VLOOKUP(B2,公会宝库商品!A:K,11,0) -> 进阶石 | E2: =VLOOKUP(B2,公会宝库商品!A:B,2,0) -> 3:100001:100
A3: 2 | B3: 1004 | C3: 5 | D3: =VLOOKUP(B3,公会宝库商品!A:K,11,0) -> 太乙精金 | E3: =VLOOKUP(B3,公会宝库商品!A:B,2,0) -> 3:100002:100
A4: 3 | B4: 1006 | C4: 60 | D4: =VLOOKUP(B4,公会宝库商品!A:K,11,0) -> 普通寻宝券 | E4: =VLOOKUP(B4,公会宝库商品!A:B,2,0) -> 3:100005:1
A5: 4 | B5: 1008 | C5: 9 | D5: =VLOOKUP(B5,公会宝库商品!A:K,11,0) -> 高级寻宝券 | E5: =VLOOKUP(B5,公会宝库商品!A:B,2,0) -> 3:100006:1
A6: 5 | B6: 1010 | C6: 10 | D6: =VLOOKUP(B6,公会宝库商品!A:K,11,0) -> 碧玉髓 | E6: =VLOOKUP(B6,公会宝库商品!A:B,2,0) -> 3:100008:1
A7: 6 | B7: 1012 | C7: 50 | D7: =VLOOKUP(B7,公会宝库商品!A:K,11,0) -> 普通点将券 | E7: =VLOOKUP(B7,公会宝库商品!A:B,2,0) -> 3:100021:1
A8: 7 | B8: 1014 | C8: 20 | D8: =VLOOKUP(B8,公会宝库商品!A:K,11,0) -> 高级点将券 | E8: =VLOOKUP(B8,公会宝库商品!A:B,2,0) -> 3:100022:1
A9: 8 | B9: 1016 | C9: 5 | D9: =VLOOKUP(B9,公会宝库商品!A:K,11,0) -> 演武场挑战券 | E9: =VLOOKUP(B9,公会宝库商品!A:B,2,0) -> 3:100023:10
A10: 9 | B10: 1018 | C10: 5 | D10: =VLOOKUP(B10,公会宝库商品!A:K,11,0) -> 命签 | E10: =VLOOKUP(B10,公会宝库商品!A:B,2,0) -> 3:100025:1
A11: 10 | B11: 1020 | C11: 99 | D11: =VLOOKUP(B11,公会宝库商品!A:K,11,0) -> 悬赏刷新券 | E11: =VLOOKUP(B11,公会宝库商品!A:B,2,0) -> 3:100027:10
A12: 12 | B12: 1036 | C12: 100 | D12: =VLOOKUP(B12,公会宝库商品!A:K,11,0) -> 邓婵玉 | E12: =VLOOKUP(B12,公会宝库商品!A:B,2,0) -> 4:601015:1
A13: 13 | B13: 1045 | C13: 100 | D13: =VLOOKUP(B13,公会宝库商品!A:K,11,0) -> 南极仙子 | E13: =VLOOKUP(B13,公会宝库商品!A:B,2,0) -> 4:602016:1
... A34: 34 | B34: 1100 | C34: 5 | D34: =VLOOKUP(B34,公会宝库商品!A:K,11,0) -> 装备 | E34: =VLOOKUP(B34,公会宝库商品!A:B,2,0) -> 2:19000408:1
A35: 35 | B35: 1101 | C35: 50 | D35: 修为丹
A36: 36 | B36: 1102 | C36: 30 | D36: 秘笈

Sheet 公会战获胜掉落奖励
A1: ID | B1: 商品ID | C1: 数量 | D1: 类型 | E1: 权重
A2: 1 | B2: 1028 | C2: 10 | D2: 1 | F2: 魂丹 | G2: =VLOOKUP(B2,公会宝库商品!A:K,2,0) -> 3:100059:1
A3: 2 | B3: 1030 | C3: 10 | D3: 1 | F3: 玄铁 | G3: =VLOOKUP(B3,公会宝库商品!A:K,2,0) -> 3:100212:1
A4: 3 | B4: 1002 | C4: 10 | D4: 1 | F4: =VLOOKUP(B4,公会宝库商品!A:K,11,0) -> 进阶石 | G4: =VLOOKUP(B4,公会宝库商品!A:K,2,0) -> 3:100001:100
A5: 4 | B5: 1006 | C5: 30 | D5: 1 | F5: =VLOOKUP(B5,公会宝库商品!A:K,11,0) -> 普通寻宝券 | G5: =VLOOKUP(B5,公会宝库商品!A:K,2,0) -> 3:100005:1
A6: 5 | B6: 1008 | C6: 5 | D6: 1 | F6: =VLOOKUP(B6,公会宝库商品!A:K,11,0) -> 高级寻宝券 | G6: =VLOOKUP(B6,公会宝库商品!A:K,2,0) -> 3:100006:1
A7: 6 | B7: 1012 | C7: 30 | D7: 1 | F7: =VLOOKUP(B7,公会宝库商品!A:K,11,0) -> 普通点将券 | G7: =VLOOKUP(B7,公会宝库商品!A:K,2,0) -> 3:100021:1
A8: 7 | B8: 1014 | C8: 10 | D8: 1 | F8: =VLOOKUP(B8,公会宝库商品!A:K,11,0) -> 高级点将券 | G8: =VLOOKUP(B8,公会宝库商品!A:K,2,0) -> 3:100022:1
A9: 8 | B9: 1018 | C9: 1 | D9: 1 | F9: =VLOOKUP(B9,公会宝库商品!A:K,11,0) -> 命签 | G9: =VLOOKUP(B9,公会宝库商品!A:K,2,0) -> 3:100025:1
A10: 9 | B10: 1036 | C10: 50 | D10: 1 | F10: =VLOOKUP(B10,公会宝库商品!A:K,11,0) -> 邓婵玉 | G10: =VLOOKUP(B10,公会宝库商品!A:K,2,0) -> 4:601015:1
A11: 10 | B11: 1045 | C11: 50 | D11: 1 | F11: =VLOOKUP(B11,公会宝库商品!A:K,11,0) -> 南极仙子 | G11: =VLOOKUP(B11,公会宝库商品!A:K,2,0) -> 4:602016:1
A12: 11 | B12: 1054 | C12: 50 | D12: 1 | F12: =VLOOKUP(B12,公会宝库商品!A:K,11,0) -> 金乌 | G12: =VLOOKUP(B12,公会宝库商品!A:K,2,0) -> 4:603019:1
A13: 12 | B13: 1050 | C13: 50 | D13: 2 | E13: 5 | F13: =VLOOKUP(B13,公会宝库商品!A:K,11,0) -> 共工 | G13: =VLOOKUP(B13,公会宝库商品!A:K,2,0) -> 4:604012:1
A14: 13 | B14: 1064 | C14: 50 | D14: 2 | E14: 5 | F14: =VLOOKUP(B14,公会宝库商品!A:K,11,0) -> 黄泉 | G14: =VLOOKUP(B14,公会宝库商品!A:K,2,0) -> 4:605010:1
A15: 14 | B15: 1040 | C15: 50 | D15: 2 | E15: 15 | F15: =VLOOKUP(B15,公会宝库商品!A:K,11,0) -> 嫦娥 | G15: =VLOOKUP(B15,公会宝库商品!A:K,2,0) -> 4:601016:1
A16: 15 | B16: 1041 | C16: 50 | D16: 2 | E16: 15 | F16: =VLOOKUP(B16,公会宝库商品!A:K,11,0) -> 姬发 | G16: =VLOOKUP(B16,公会宝库商品!A:K,2,0) -> 4:601018:1
A17: 16 | B17: 1048 | C17: 50 | D17: 2 | E17: 15 | F17: =VLOOKUP(B17,公会宝库商品!A:K,11,0) -> 禄缘上仙 | G17: =VLOOKUP(B17,公会宝库商品!A:K,2,0) -> 4:602017:1
A18: 17 | B18: 1049 | C18: 50 | D18: 2 | E18: 15 | F18: =VLOOKUP(B18,公会宝库商品!A:K,11,0) -> 斗战胜佛 | G18: =VLOOKUP(B18,公会宝库商品!A:K,2,0) -> 4:602018:1
A19: 18 | B19: 1059 | C19: 50 | D19: 2 | E19: 15 | F19: =VLOOKUP(B19,公会宝库商品!A:K,11,0) -> 石矶 | G19: =VLOOKUP(B19,公会宝库商品!A:K,2,0) -> 4:603015:1
A20: 19 | B20: 1060 | C20: 50 | D20: 2 | E20: 15 | F20: =VLOOKUP(B20,公会宝库商品!A:K,11,0) -> 敖丙 | G20: =VLOOKUP(B20,公会宝库商品!A:K,2,0) -> 4:603020:1
A21: 20 | B21: 1101 | C21: 10 | D21: 2 | E21: 20
A22: 21 | B22: 1102 | C22: 10 | D22: 2 | E22: 20

Sheet 公会宝库提示
A1: 提示ID | B1: 文本
A2: 1 | B2: Chào mừng! ~
A3: 2 | B3: Không phải bất cứ thứ gì cũng có thể được đưa vào nhà kho báu!
A4: 3 | B4: Bạn có thể nhận được sự đóng góp của Liên minh Tiên từ Trận chiến Liên minh Tiên, vì vậy hãy nhớ tham gia!
A5: 4 | B5: Kho báu sẽ được dọn dẹp thường xuyên, vui lòng đổi nó càng sớm càng tốt.
A6: 5 | B6: Tiêu diệt BOSS của Liên minh Bất tử để nhận được Đóng góp của Liên minh Bất tử!
A7: 6 | B7: Những đóng góp từ Liên minh Bất tử có thể nâng cấp các kỹ năng của Liên minh Bất tử!
A8: 7 | B8: Bạn chỉ có thể đặt đồ vật vào Nhà kho báu của Liên minh Bất tử 20 lần một ngày.

Sheet Sheet2
A1: 商品内容
A2: 3:100001:100 | B2: =VLOOKUP($A2,公会宝库商品!$B:$K,COLUMN(Sheet2!B2),0) -> 500 | C2: =VLOOKUP($A2,公会宝库商品!$B:$K,COLUMN(Sheet2!C2),0) -> 100 | D2: =VLOOKUP($A2,公会宝库商品!$B:$K,COLUMN(Sheet2!D2),0) -> 999 | E2: =VLOOKUP($A2,公会宝库商品!$B:$K,COLUMN(Sheet2!E2),0) -> -1 | F2: =VLOOKUP($A2,公会宝库商品!$B:$K,COLUMN(Sheet2!F2),0) -> 9999 | G2: =VLOOKUP($A2,公会宝库商品!$B:$K,COLUMN(Sheet2!G2),0) -> 2 | H2: =VLOOKUP($A2,公会宝库商品!$B:$K,COLUMN(Sheet2!H2),0) -> 1
A3: 3:100002:100 | B3: =VLOOKUP($A3,公会宝库商品!$B:$K,COLUMN(Sheet2!B3),0) -> 10000 | C3: =VLOOKUP($A3,公会宝库商品!$B:$K,COLUMN(Sheet2!C3),0) -> 2000 | D3: =VLOOKUP($A3,公会宝库商品!$B:$K,COLUMN(Sheet2!D3),0) -> 999 | E3: =VLOOKUP($A3,公会宝库商品!$B:$K,COLUMN(Sheet2!E3),0) -> -1 | F3: =VLOOKUP($A3,公会宝库商品!$B:$K,COLUMN(Sheet2!F3),0) -> 9999 | G3: =VLOOKUP($A3,公会宝库商品!$B:$K,COLUMN(Sheet2!G3),0) -> 2 | H3: =VLOOKUP($A3,公会宝库商品!$B:$K,COLUMN(Sheet2!H3),0) -> 1
A4: 3:100004:100 | B4: =VLOOKUP($A4,公会宝库商品!$B:$K,COLUMN(Sheet2!B4),0) -> #N/A | C4: =VLOOKUP($A4,公会宝库商品!$B:$K,COLUMN(Sheet2!C4),0) -> #N/A | D4: =VLOOKUP($A4,公会宝库商品!$B:$K,COLUMN(Sheet2!D4),0) -> #N/A | E4: =VLOOKUP($A4,公会宝库商品!$B:$K,COLUMN(Sheet2!E4),0) -> #N/A | F4: =VLOOKUP($A4,公会宝库商品!$B:$K,COLUMN(Sheet2!F4),0) -> #N/A | G4: =VLOOKUP($A4,公会宝库商品!$B:$K,COLUMN(Sheet2!G4),0) -> #N/A | H4: =VLOOKUP($A4,公会宝库商品!$B:$K,COLUMN(Sheet2!H4),0) -> #N/A
A5: 3:100005:10 | B5: =VLOOKUP($A5,公会宝库商品!$B:$K,COLUMN(Sheet2!B5),0) -> #N/A | C5: =VLOOKUP($A5,公会宝库商品!$B:$K,COLUMN(Sheet2!C5),0) -> #N/A | D5: =VLOOKUP($A5,公会宝库商品!$B:$K,COLUMN(Sheet2!D5),0) -> #N/A | E5: =VLOOKUP($A5,公会宝库商品!$B:$K,COLUMN(Sheet2!E5),0) -> #N/A | F5: =VLOOKUP($A5,公会宝库商品!$B:$K,COLUMN(Sheet2!F5),0) -> #N/A | G5: =VLOOKUP($A5,公会宝库商品!$B:$K,COLUMN(Sheet2!G5),0) -> #N/A | H5: =VLOOKUP($A5,公会宝库商品!$B:$K,COLUMN(Sheet2!H5),0) -> #N/A
A6: 3:100006:1 | B6: =VLOOKUP($A6,公会宝库商品!$B:$K,COLUMN(Sheet2!B6),0) -> 1000 | C6: =VLOOKUP($A6,公会宝库商品!$B:$K,COLUMN(Sheet2!C6),0) -> 250 | D6: =VLOOKUP($A6,公会宝库商品!$B:$K,COLUMN(Sheet2!D6),0) -> 999 | E6: =VLOOKUP($A6,公会宝库商品!$B:$K,COLUMN(Sheet2!E6),0) -> -1 | F6: =VLOOKUP($A6,公会宝库商品!$B:$K,COLUMN(Sheet2!F6),0) -> 9999 | G6: =VLOOKUP($A6,公会宝库商品!$B:$K,COLUMN(Sheet2!G6),0) -> 2 | H6: =VLOOKUP($A6,公会宝库商品!$B:$K,COLUMN(Sheet2!H6),0) -> 1
A7: 3:100008:1 | B7: =VLOOKUP($A7,公会宝库商品!$B:$K,COLUMN(Sheet2!B7),0) -> 650 | C7: =VLOOKUP($A7,公会宝库商品!$B:$K,COLUMN(Sheet2!C7),0) -> 100 | D7: =VLOOKUP($A7,公会宝库商品!$B:$K,COLUMN(Sheet2!D7),0) -> 999 | E7: =VLOOKUP($A7,公会宝库商品!$B:$K,COLUMN(Sheet2!E7),0) -> -1 | F7: =VLOOKUP($A7,公会宝库商品!$B:$K,COLUMN(Sheet2!F7),0) -> 9999 | G7: =VLOOKUP($A7,公会宝库商品!$B:$K,COLUMN(Sheet2!G7),0) -> 2 | H7: =VLOOKUP($A7,公会宝库商品!$B:$K,COLUMN(Sheet2!H7),0) -> 1
A8: 3:100021:10 | B8: =VLOOKUP($A8,公会宝库商品!$B:$K,COLUMN(Sheet2!B8),0) -> #N/A | C8: =VLOOKUP($A8,公会宝库商品!$B:$K,COLUMN(Sheet2!C8),0) -> #N/A | D8: =VLOOKUP($A8,公会宝库商品!$B:$K,COLUMN(Sheet2!D8),0) -> #N/A | E8: =VLOOKUP($A8,公会宝库商品!$B:$K,COLUMN(Sheet2!E8),0) -> #N/A | F8: =VLOOKUP($A8,公会宝库商品!$B:$K,COLUMN(Sheet2!F8),0) -> #N/A | G8: =VLOOKUP($A8,公会宝库商品!$B:$K,COLUMN(Sheet2!G8),0) -> #N/A | H8: =VLOOKUP($A8,公会宝库商品!$B:$K,COLUMN(Sheet2!H8),0) -> #N/A
A9: 3:100022:1 | B9: =VLOOKUP($A9,公会宝库商品!$B:$K,COLUMN(Sheet2!B9),0) -> 1250 | C9: =VLOOKUP($A9,公会宝库商品!$B:$K,COLUMN(Sheet2!C9),0) -> 250 | D9: =VLOOKUP($A9,公会宝库商品!$B:$K,COLUMN(Sheet2!D9),0) -> 999 | E9: =VLOOKUP($A9,公会宝库商品!$B:$K,COLUMN(Sheet2!E9),0) -> -1 | F9: =VLOOKUP($A9,公会宝库商品!$B:$K,COLUMN(Sheet2!F9),0) -> 9999 | G9: =VLOOKUP($A9,公会宝库商品!$B:$K,COLUMN(Sheet2!G9),0) -> 2 | H9: =VLOOKUP($A9,公会宝库商品!$B:$K,COLUMN(Sheet2!H9),0) -> 1
A10: 3:100023:10 | B10: =VLOOKUP($A10,公会宝库商品!$B:$K,COLUMN(Sheet2!B10),0) -> 1000 | C10: =VLOOKUP($A10,公会宝库商品!$B:$K,COLUMN(Sheet2!C10),0) -> 200 | D10: =VLOOKUP($A10,公会宝库商品!$B:$K,COLUMN(Sheet2!D10),0) -> 999 | E10: =VLOOKUP($A10,公会宝库商品!$B:$K,COLUMN(Sheet2!E10),0) -> -1 | F10: =VLOOKUP($A10,公会宝库商品!$B:$K,COLUMN(Sheet2!F10),0) -> 9999 | G10: =VLOOKUP($A10,公会宝库商品!$B:$K,COLUMN(Sheet2!G10),0) -> 2 | H10: =VLOOKUP($A10,公会宝库商品!$B:$K,COLUMN(Sheet2!H10),0) -> 1
A11: 3:100025:1 | B11: =VLOOKUP($A11,公会宝库商品!$B:$K,COLUMN(Sheet2!B11),0) -> 5000 | C11: =VLOOKUP($A11,公会宝库商品!$B:$K,COLUMN(Sheet2!C11),0) -> 1200 | D11: =VLOOKUP($A11,公会宝库商品!$B:$K,COLUMN(Sheet2!D11),0) -> 999 | E11: =VLOOKUP($A11,公会宝库商品!$B:$K,COLUMN(Sheet2!E11),0) -> -1 | F11: =VLOOKUP($A11,公会宝库商品!$B:$K,COLUMN(Sheet2!F11),0) -> 9999 | G11: =VLOOKUP($A11,公会宝库商品!$B:$K,COLUMN(Sheet2!G11),0) -> 2 | H11: =VLOOKUP($A11,公会宝库商品!$B:$K,COLUMN(Sheet2!H11),0) -> 1
A12: 3:100027:10 | B12: =VLOOKUP($A12,公会宝库商品!$B:$K,COLUMN(Sheet2!B12),0) -> 1500 | C12: =VLOOKUP($A12,公会宝库商品!$B:$K,COLUMN(Sheet2!C12),0) -> 300 | D12: =VLOOKUP($A12,公会宝库商品!$B:$K,COLUMN(Sheet2!D12),0) -> 999 | E12: =VLOOKUP($A12,公会宝库商品!$B:$K,COLUMN(Sheet2!E12),0) -> -1 | F12: =VLOOKUP($A12,公会宝库商品!$B:$K,COLUMN(Sheet2!F12),0) -> 9999 | G12: =VLOOKUP($A12,公会宝库商品!$B:$K,COLUMN(Sheet2!G12),0) -> 2 | H12: =VLOOKUP($A12,公会宝库商品!$B:$K,COLUMN(Sheet2!H12),0) -> 1
A13: 3:100030:10 | B13: =VLOOKUP($A13,公会宝库商品!$B:$K,COLUMN(Sheet2!B13),0) -> #N/A | C13: =VLOOKUP($A13,公会宝库商品!$B:$K,COLUMN(Sheet2!C13),0) -> #N/A | D13: =VLOOKUP($A13,公会宝库商品!$B:$K,COLUMN(Sheet2!D13),0) -> #N/A | E13: =VLOOKUP($A13,公会宝库商品!$B:$K,COLUMN(Sheet2!E13),0) -> #N/A | F13: =VLOOKUP($A13,公会宝库商品!$B:$K,COLUMN(Sheet2!F13),0) -> #N/A | G13: =VLOOKUP($A13,公会宝库商品!$B:$K,COLUMN(Sheet2!G13),0) -> #N/A | H13: =VLOOKUP($A13,公会宝库商品!$B:$K,COLUMN(Sheet2!H13),0) -> #N/A
... A98: 2:19000408:1 | B98: =VLOOKUP($A98,公会宝库商品!$B:$K,COLUMN(Sheet2!B98),0) -> 2025 | C98: =VLOOKUP($A98,公会宝库商品!$B:$K,COLUMN(Sheet2!C98),0) -> 405 | D98: =VLOOKUP($A98,公会宝库商品!$B:$K,COLUMN(Sheet2!D98),0) -> 999 | E98: =VLOOKUP($A98,公会宝库商品!$B:$K,COLUMN(Sheet2!E98),0) -> -1 | F98: =VLOOKUP($A98,公会宝库商品!$B:$K,COLUMN(Sheet2!F98),0) -> 9999 | G98: =VLOOKUP($A98,公会宝库商品!$B:$K,COLUMN(Sheet2!G98),0) -> 1 | H98: =VLOOKUP($A98,公会宝库商品!$B:$K,COLUMN(Sheet2!H98),0) -> 1

Sheet Sheet1
A1: 英雄ID | B1: 英雄名 | C1: 星级 | H1: 李靖
A2: 2000 | B2: TM_白板_近战 | C2: 5 | H2: 邓婵玉
A3: 2023 | B3: TM_白板_远程 | C3: 5 | H3: 嫦娥
A4: 100101 | B4: 方术士 | C4: 1 | H4: 后羿
A5: 100201 | B5: 医师 | C5: 2 | H5: 姬发
A6: 100301 | B6: 长弓手 | C6: 2 | H6: 杨戬
A7: 100401 | B7: 金吾卫 | C7: 3 | H7: 哪吒
A8: 100501 | B8: 虎豹骑 | C8: 3 | H8: 姜子牙
A9: 100601 | B9: 殿前禁卫 | C9: 3 | H9: 雷震子
A10: 100701 | B10: 燕赤侠 | C10: 3 | H10: 天蓬元帅
A11: 100801 | B11: 木吒 | C11: 3 | H11: 卷帘大将
A12: 100901 | B12: 黄飞虎 | C12: 4 | H12: 南极仙子
A13: 100902 | B13: 黄飞虎 | C13: 5 | H13: 禄缘上仙
... A39: 101509 | B39: 邓婵玉 | C39: 13 | H39: 蚩尤
A40: 101601 | B40: 嫦娥 | C40: 5 | H40: 孟婆
A41: 101602 | B41: 嫦娥 | C41: 6 | H41: 刑天
A42: 101603 | B42: 嫦娥 | C42: 7 | H42: 魔·悟空
A43: 101604 | B43: 嫦娥 | C43: 8 | H43: 黄泉
A44: 101605 | B44: 嫦娥 | C44: 9 | H44: 阎君
A45: 101606 | B45: 嫦娥 | C45: 10 | H45: 东皇太一
A46: 101607 | B46: 嫦娥 | C46: 11
A47: 101608 | B47: 嫦娥 | C47: 12
A48: 101609 | B48: 嫦娥 | C48: 13
A49: 101701 | B49: 后羿 | C49: 5
A50: 101702 | B50: 后羿 | C50: 6
A51: 101703 | B51: 后羿 | C51: 7
A52: 101704 | B52: 后羿 | C52: 8
A53: 101705 | B53: 后羿 | C53: 9
A54: 101706 | B54: 后羿 | C54: 10
A55: 101707 | B55: 后羿 | C55: 11
A56: 101708 | B56: 后羿 | C56: 12
A57: 101709 | B57: 后羿 | C57: 13
A58: 101801 | B58: 姬发 | C58: 5
A59: 101802 | B59: 姬发 | C59: 6
A60: 101803 | B60: 姬发 | C60: 7
A61: 101804 | B61: 姬发 | C61: 8
A62: 101805 | B62: 姬发 | C62: 9
A63: 101806 | B63: 姬发 | C63: 10
A64: 101807 | B64: 姬发 | C64: 11
A65: 101808 | B65: 姬发 | C65: 12
...

Sheet Sheet3
A1: 李靖 | B1: =VLOOKUP(A1,公会宝库商品!K:K,2,0) -> #REF!
A2: 邓婵玉 | B2: =VLOOKUP(A2,公会宝库商品!K:K,2,0) -> #REF!
A3: 嫦娥 | B3: =VLOOKUP(A3,公会宝库商品!K:K,2,0) -> #REF!
A4: 后羿 | B4: =VLOOKUP(A4,公会宝库商品!K:K,2,0) -> #REF!
A5: 姬发 | B5: =VLOOKUP(A5,公会宝库商品!K:K,2,0) -> #REF!
A6: 杨戬 | B6: =VLOOKUP(A6,公会宝库商品!K:K,2,0) -> #N/A
A7: 哪吒 | B7: =VLOOKUP(A7,公会宝库商品!K:K,2,0) -> #REF!
A8: 姜子牙 | B8: =VLOOKUP(A8,公会宝库商品!K:K,2,0) -> #REF!
A9: 雷震子 | B9: =VLOOKUP(A9,公会宝库商品!K:K,2,0) -> #REF!
A10: 天蓬元帅 | B10: =VLOOKUP(A10,公会宝库商品!K:K,2,0) -> #REF!
A11: 卷帘大将 | B11: =VLOOKUP(A11,公会宝库商品!K:K,2,0) -> #REF!
A12: 南极仙子 | B12: =VLOOKUP(A12,公会宝库商品!K:K,2,0) -> #REF!
... A45: 东皇太一 | B45: =VLOOKUP(A45,公会宝库商品!K:K,2,0) -> #REF!
