Workbook

Sheet 英雄召唤
A1: 召唤类型 | B1: *备注 | C1: 召唤次数 | D1: VIP要求 | E1: 消耗道具ID | F1: 消耗道具数量 | G1: 消耗友情点 | H1: 消耗召唤积分 | I1: 消耗元宝 | J1: 允许混合抽 | K1: 混合抽单次元宝价格 | L1: 免费刷新间隔 | M1: 免费次数上限 | N1: 奖励召唤积分 | O1: 元宝送经验 | P1: 星组配置 | Q1: 星组配置说明（策划自己看看） | R1: 启用脸黑 | S1: 理想星级 | T1: 不幸召唤次数上限 | U1: 幸运星组 | V1: 启用保底 | W1: 保底星级 | X1: 保底星组 | Y1: 启用脸白 | Z1: 幸运召唤次数上限 | AA1: 不幸星组
A2: 1 | B2: Cơ sở triệu hoán 1 Lần | C2: 1 | E2: 100021 | F2: 1 | L2: 86400 | M2: 1 | N2: 1 | O2: 0 | P2: 1:10000 | Q2: 50%概率进入1星组，30%进入2星组，20%进入3星组
A3: 2 | B3: Cơ sở triệu hoán 10 Lần | C3: 10 | E3: 100021 | F3: 10 | N3: 10 | O3: 0 | P3: 1:10000
A4: 3 | B4: Hữu nghị triệu hoán 1 Lần | C4: 1 | G4: 100 | N4: 2 | O4: 0 | P4: 2:10000
A5: 4 | B5: Hữu nghị triệu hoán 10 Lần | C5: 10 | G5: 1000 | N5: 20 | O5: 0 | P5: 2:10000
A6: 5 | B6: Cao cấp triệu hoán 1 Lần | C6: 1 | E6: 100022 | F6: 1 | I6: 220 | L6: 86400 | M6: 1 | N6: 20 | O6: 5000 | P6: 3:10000 | R6: 1 | S6: 5 | T6: 39 | U6: 35
A7: 6 | B7: Cao cấp triệu hoán 10 Lần | C7: 10 | D7: 6 | E7: 100022 | F7: 10 | I7: 2000 | K7: 220 | N7: 200 | O7: 50000 | P7: 3:10000 | R7: 1 | S7: 5 | T7: 39 | U7: 35 | V7: 1 | W7: 4 | X7: 4 | Y7: 1 | Z7: 1 | AA7: 5
A8: 7 | B8: Điểm tích lũy triệu hoán | C8: 1 | D8: 7 | H8: 1000 | N8: 0 | O8: 0 | P8: 35:10000
A9: 8 | B9: Biết võ khoán triệu hoán 1 Lần | C9: 1 | E9: 100298 | F9: 1 | N9: 10 | P9: 103:10000 | Y9: 1 | Z9: 1 | AA9: 5
A10: 9 | B10: Biết võ triệu hoán 10 Lần | C10: 10 | E10: 100298 | F10: 10 | N10: 100 | P10: 103:10000 | Y10: 1 | Z10: 1 | AA10: 5

Sheet 英雄召唤星组
A1: ID | B1: 英雄ID | C1: *权重 | D1: 所属星组 | E1: 突出显示 | F1: *名字 | G1: *闪烁之光角色 | H1: 展示权重
A2: 1 | B2: 201301 | C2: 100 | D2: 99 | E2: 1 | F2: 雨师 | G2: 水元素 | H2: 100
A3: 2 | B3: 200101 | C3: 8500 | D3: 1 | E3: 1 | F3: =VLOOKUP(B3,[1]英雄基础!$A:$E,5,0) -> 仙童 | G3: =VLOOKUP(B3,[1]英雄基础!$A:$D,4,0) -> 莉莉丝 | H3: 8500
A4: 3 | B4: 100101 | C4: 8500 | D4: 1 | E4: 1 | F4: =VLOOKUP(B4,[1]英雄基础!$A:$E,5,0) -> 方术士 | G4: =VLOOKUP(B4,[1]英雄基础!$A:$D,4,0) -> 树精灵 | H4: 8500
A5: 4 | B5: 300101 | C5: 8500 | D5: 1 | E5: 1 | F5: =VLOOKUP(B5,[1]英雄基础!$A:$E,5,0) -> 将臣 | G5: =VLOOKUP(B5,[1]英雄基础!$A:$D,4,0) -> 地狱犬 | H5: 8500
A6: 5 | B6: 200201 | C6: 6000 | D6: 1 | E6: 1 | F6: =VLOOKUP(B6,[1]英雄基础!$A:$E,5,0) -> 日游神 | G6: =VLOOKUP(B6,[1]英雄基础!$A:$D,4,0) -> 兽族步兵 | H6: 6000
A7: 6 | B7: 300301 | C7: 6000 | D7: 1 | E7: 1 | F7: =VLOOKUP(B7,[1]英雄基础!$A:$E,5,0) -> 花妖 | G7: =VLOOKUP(B7,[1]英雄基础!$A:$D,4,0) -> 死灵巫师 | H7: 6000
A8: 7 | B8: 100301 | C8: 6000 | D8: 1 | E8: 1 | F8: =VLOOKUP(B8,[1]英雄基础!$A:$E,5,0) -> 长弓手 | G8: =VLOOKUP(B8,[1]英雄基础!$A:$D,4,0) -> 精灵射手 | H8: 6000
A9: 8 | B9: 300701 | C9: 700 | D9: 1 | E9: 1 | F9: =VLOOKUP(B9,[1]英雄基础!$A:$E,5,0) -> 玉兔 | G9: =VLOOKUP(B9,[1]英雄基础!$A:$D,4,0) -> 地狱火 | H9: 700
A10: 9 | B10: 200801 | C10: 700 | D10: 1 | E10: 1 | F10: =VLOOKUP(B10,[1]英雄基础!$A:$E,5,0) -> 笛仙 | G10: =VLOOKUP(B10,[1]英雄基础!$A:$D,4,0) -> 美狄亚 | H10: 700
A11: 10 | B11: 100601 | C11: 700 | D11: 1 | E11: 1 | F11: =VLOOKUP(B11,[1]英雄基础!$A:$E,5,0) -> 殿前禁卫 | G11: =VLOOKUP(B11,[1]英雄基础!$A:$D,4,0) -> 树界守卫 | H11: 700
A12: 11 | B12: 300401 | C12: 700 | D12: 1 | E12: 1 | F12: =VLOOKUP(B12,[1]英雄基础!$A:$E,5,0) -> 黑风 | G12: =VLOOKUP(B12,[1]英雄基础!$A:$D,4,0) -> 末日守卫 | H12: 700
A13: 12 | B13: 100801 | C13: 700 | D13: 1 | E13: 1 | F13: =VLOOKUP(B13,[1]英雄基础!$A:$E,5,0) -> 木吒 | G13: =VLOOKUP(B13,[1]英雄基础!$A:$D,4,0) -> 风暴猎手 | H13: 700
A14: 13 | B14: 500101 | C14: 700 | D14: 1 | E14: 1 | F14: =VLOOKUP(B14,[1]英雄基础!$A:$E,5,0) -> 鲛姬 | G14: =VLOOKUP(B14,[1]英雄基础!$A:$D,4,0) -> 巨魔巫医 | H14: 700
... A40: 39 | B40: 101701 | C40: 2 | D40: 1 | E40: 1 | F40: =VLOOKUP(B40,[1]英雄基础!$A:$E,5,0) -> 后羿 | G40: =VLOOKUP(B40,[1]英雄基础!$A:$D,4,0) -> 芬尼尔 | H40: 2
A41: 40 | B41: 102301 | C41: 2 | D41: 1 | E41: 1 | F41: 花木兰 | G41: =VLOOKUP(B41,[1]英雄基础!$A:$D,4,0) -> 原创英雄 | H41: 2
A42: 41 | B42: 301401 | C42: 6 | D42: 1 | E42: 1 | F42: =VLOOKUP(B42,[1]英雄基础!$A:$E,5,0) -> 红孩儿 | G42: =VLOOKUP(B42,[1]英雄基础!$A:$D,4,0) -> 菲尼克斯 | H42: 6
A43: 42 | B43: 301701 | C43: 14 | D43: 1 | E43: 1 | F43: =VLOOKUP(B43,[1]英雄基础!$A:$E,5,0) -> 牛魔王 | G43: =VLOOKUP(B43,[1]英雄基础!$A:$D,4,0) -> 炽天使 | H43: 14
A44: 43 | B44: 301601 | C44: 2 | D44: 1 | E44: 1 | F44: =VLOOKUP(B44,[1]英雄基础!$A:$E,5,0) -> 混天大圣 | G44: =VLOOKUP(B44,[1]英雄基础!$A:$D,4,0) -> 洛基 | H44: 2
A45: 44 | B45: 301801 | C45: 14 | D45: 1 | E45: 1 | F45: =VLOOKUP(B45,[1]英雄基础!$A:$E,5,0) -> 擎苍 | G45: =VLOOKUP(B45,[1]英雄基础!$A:$D,4,0) -> 剑豪卡赞 | H45: 14
A46: 45 | B46: 302001 | C46: 4 | D46: 1 | E46: 1 | F46: =VLOOKUP(B46,[1]英雄基础!$A:$E,5,0) -> 敖丙 | G46: =VLOOKUP(B46,[1]英雄基础!$A:$D,4,0) -> 瓦尔基里 | H46: 4
A47: 46 | B47: 302101 | C47: 14 | D47: 1 | E47: 1 | F47: =VLOOKUP(B47,[1]英雄基础!$A:$E,5,0) -> 白骨夫人 | G47: =VLOOKUP(B47,[1]英雄基础!$A:$D,4,0) -> 炎魔之王 | H47: 14
A48: 47 | B48: 301901 | C48: 13 | D48: 1 | E48: 1 | F48: =VLOOKUP(B48,[1]英雄基础!$A:$E,5,0) -> 金乌 | G48: =VLOOKUP(B48,[1]英雄基础!$A:$D,4,0) -> 吸血伯爵 | H48: 14
A49: 48 | B49: 302201 | C49: 6 | D49: 1 | E49: 1 | F49: =VLOOKUP(B49,[1]英雄基础!$A:$E,5,0) -> 妲己 | G49: =VLOOKUP(B49,[1]英雄基础!$A:$D,4,0) -> 阿波罗 | H49: 6
A50: 49 | B50: 301501 | C50: 6 | D50: 1 | E50: 1 | F50: =VLOOKUP(B50,[1]英雄基础!$A:$E,5,0) -> 石矶 | G50: =VLOOKUP(B50,[1]英雄基础!$A:$D,4,0) -> 普罗米修斯 | H50: 6
A51: 50 | B51: 201401 | C51: 14 | D51: 1 | E51: 1 | F51: =VLOOKUP(B51,[1]英雄基础!$A:$E,5,0) -> 天蓬元帅 | G51: =VLOOKUP(B51,[1]英雄基础!$A:$D,4,0) -> 阿瑞斯 | H51: 14
A52: 51 | B52: 202001 | C52: 6 | D52: 1 | E52: 1 | F52: =VLOOKUP(B52,[1]英雄基础!$A:$E,5,0) -> 通天教主 | G52: =VLOOKUP(B52,[1]英雄基础!$A:$D,4,0) -> 冰霜巨龙 | H52: 6
A53: 52 | B53: 201601 | C53: 15 | D53: 1 | E53: 1 | F53: =VLOOKUP(B53,[1]英雄基础!$A:$E,5,0) -> 南极仙子 | G53: =VLOOKUP(B53,[1]英雄基础!$A:$D,4,0) -> 派西斯 | H53: 15
... A58: 57 | B58: 201501 | C58: 6 | D58: 1 | E58: 1 | F58: =VLOOKUP(B58,[1]英雄基础!$A:$E,5,0) -> 卷帘大将 | G58: =VLOOKUP(B58,[1]英雄基础!$A:$D,4,0) -> 泰坦 | H58: 6
A59: 58 | B59: 202401 | C59: 6 | D59: 1 | E59: 1 | F59: 玄奘 | G59: =VLOOKUP(B59,[1]英雄基础!$A:$D,4,0) -> 利维坦 | H59: 6
A60: 59 | B60: 202301 | C60: 6 | D60: 1 | E60: 1 | F60: 白龙 | G60: =VLOOKUP(B60,[1]英雄基础!$A:$D,4,0) -> 原创英雄 | H60: 6
A61: 60 | B61: 501201 | C61: 2 | D61: 1 | E61: 1 | F61: =VLOOKUP(B61,[1]英雄基础!$A:$E,5,0) -> 东皇太一 | G61: =VLOOKUP(B61,[1]英雄基础!$A:$D,4,0) -> 阿努比斯 | H61: 2
A62: 61 | B62: 500701 | C62: 1 | D62: 1 | E62: 1 | F62: =VLOOKUP(B62,[1]英雄基础!$A:$E,5,0) -> 孟婆 | G62: =VLOOKUP(B62,[1]英雄基础!$A:$D,4,0) -> 潘多拉 | H62: 1
A63: 62 | B63: 400701 | C63: 1 | D63: 1 | E63: 1 | F63: =VLOOKUP(B63,[1]英雄基础!$A:$E,5,0) -> 神农 | G63: =VLOOKUP(B63,[1]英雄基础!$A:$D,4,0) -> 拉斐尔 | H63: 1
A64: 63 | B64: 401201 | C64: 1 | D64: 1 | E64: 1 | F64: =VLOOKUP(B64,[1]英雄基础!$A:$E,5,0) -> 共工 | G64: =VLOOKUP(B64,[1]英雄基础!$A:$D,4,0) -> 赫拉 | H64: 1
A65: 64 | B65: 401301 | C65: 1 | D65: 1 | E65: 1 | F65: =VLOOKUP(B65,[1]英雄基础!$A:$E,5,0) -> 祝融 | G65: =VLOOKUP(B65,[1]英雄基础!$A:$D,4,0) -> 宙斯 | H65: 1
A66: 65 | B66: 400601 | C66: 1 | D66: 1 | E66: 1 | F66: =VLOOKUP(B66,[1]英雄基础!$A:$E,5,0) -> 盘古 | G66: =VLOOKUP(B66,[1]英雄基础!$A:$D,4,0) -> 盖亚 | H66: 1
A67: 66 | B67: 500601 | C67: 1 | D67: 1 | E67: 1 | F67: =VLOOKUP(B67,[1]英雄基础!$A:$E,5,0) -> 蚩尤 | G67: =VLOOKUP(B67,[1]英雄基础!$A:$D,4,0) -> 亚巴顿 | H67: 1
A68: 67 | B68: 400901 | C68: 1 | D68: 1 | E68: 1 | F68: =VLOOKUP(B68,[1]英雄基础!$A:$E,5,0) -> 鲲 | G68: =VLOOKUP(B68,[1]英雄基础!$A:$D,4,0) -> 神灵大祭司 | H68: 1
A69: 68 | B69: 501101 | C69: 3 | D69: 1 | E69: 1 | F69: =VLOOKUP(B69,[1]英雄基础!$A:$E,5,0) -> 阎君 | G69: =VLOOKUP(B69,[1]英雄基础!$A:$D,4,0) -> 蛇女墨莎 | H69: 3
...

Sheet 英雄召唤作弊
A1: ID | B1: 召唤模式 | C1: 召唤次数 | D1: 星组
A2: 1 | B2: 2 | C2: 1 | D2: 99
A3: 2 | B3: 2 | C3: 2 | D3: 98
A4: 3 | B4: 2 | C4: 4 | D4: 98
A5: 4 | B5: 2 | C5: 10 | D5: 1001
A6: 5 | B6: 2 | C6: 20 | D6: 1002

Sheet Sheet(基础召唤概率)
A1: 英雄ID | B1: 名字 | C1: 闪烁之光角色 | D1: 星级 | E1: 概率 | F1: 子包概率 | G1: 取后四位 | H1: 万分比计算 | I1: 修正
A2: 100101 | B2: Phương thuật sĩ | C2: =VLOOKUP(B2,[2]英雄技能!$D:$E,2,0) -> #N/A | D2: 1 | E2: 0.17821 | F2: =IF(D2=1,E2/0.53,IF(D2=2,E2/0.36,IF(D2=3,E2/0.091,IF(D2=4,E2/0.015,E2/0.004)))) -> 0.33624528 | G2: =ROUND(F2,4) -> 0.3362 | H2: =G2*10000 -> 3362 | I2: 3334
A3: 100201 | B3: Y sư | C3: =VLOOKUP(B3,[2]英雄技能!$D:$E,2,0) -> #N/A | D3: 2 | E3: 0.06 | F3: =IF(D3=1,E3/0.53,IF(D3=2,E3/0.36,IF(D3=3,E3/0.091,IF(D3=4,E3/0.015,E3/0.004)))) -> 0.16666667 | G3: =ROUND(F3,4) -> 0.1667 | H3: =G3*10000 -> 1667 | I3: 1667
A4: 100301 | B4: Trường cung tay | C4: =VLOOKUP(B4,[2]英雄技能!$D:$E,2,0) -> #N/A | D4: 2 | E4: 0.06 | F4: =IF(D4=1,E4/0.53,IF(D4=2,E4/0.36,IF(D4=3,E4/0.091,IF(D4=4,E4/0.015,E4/0.004)))) -> 0.16666667 | G4: =ROUND(F4,4) -> 0.1667 | H4: =G4*10000 -> 1667 | I4: 1667
A5: 100401 | B5: Kim Ngô Vệ | C5: =VLOOKUP(B5,[2]英雄技能!$D:$E,2,0) -> #N/A | D5: 3 | E5: 0.00535 | F5: =IF(D5=1,E5/0.53,IF(D5=2,E5/0.36,IF(D5=3,E5/0.091,IF(D5=4,E5/0.015,E5/0.004)))) -> 0.058791209 | G5: =ROUND(F5,4) -> 0.0588 | H5: =G5*10000 -> 588 | I5: 625
A6: 100501 | B6: Trước điện cấm vệ | C6: =VLOOKUP(B6,[2]英雄技能!$D:$E,2,0) -> #N/A | D6: 3 | E6: 0.00535 | F6: =IF(D6=1,E6/0.53,IF(D6=2,E6/0.36,IF(D6=3,E6/0.091,IF(D6=4,E6/0.015,E6/0.004)))) -> 0.058791209 | G6: =ROUND(F6,4) -> 0.0588 | H6: =G6*10000 -> 588 | I6: 625
A7: 100601 | B7: Hổ Báo kỵ | C7: =VLOOKUP(B7,[2]英雄技能!$D:$E,2,0) -> #N/A | D7: 3 | E7: 0.00535 | F7: =IF(D7=1,E7/0.53,IF(D7=2,E7/0.36,IF(D7=3,E7/0.091,IF(D7=4,E7/0.015,E7/0.004)))) -> 0.058791209 | G7: =ROUND(F7,4) -> 0.0588 | H7: =G7*10000 -> 588 | I7: 625
A8: 100701 | B8: Yến đỏ hiệp | C8: =VLOOKUP(B8,[2]英雄技能!$D:$E,2,0) -> #N/A | D8: 3 | E8: 0.00535 | F8: =IF(D8=1,E8/0.53,IF(D8=2,E8/0.36,IF(D8=3,E8/0.091,IF(D8=4,E8/0.015,E8/0.004)))) -> 0.058791209 | G8: =ROUND(F8,4) -> 0.0588 | H8: =G8*10000 -> 588 | I8: 625
A9: 100801 | B9: Mộc Tra | C9: =VLOOKUP(B9,[2]英雄技能!$D:$E,2,0) -> #N/A | D9: 3 | E9: 0.00535 | F9: =IF(D9=1,E9/0.53,IF(D9=2,E9/0.36,IF(D9=3,E9/0.091,IF(D9=4,E9/0.015,E9/0.004)))) -> 0.058791209 | G9: =ROUND(F9,4) -> 0.0588 | H9: =G9*10000 -> 588 | I9: 625
A10: 100901 | B10: Trụ Vương | C10: =VLOOKUP(B10,[2]英雄技能!$D:$E,2,0) -> #N/A | D10: 4 | E10: 0.00066 | F10: =IF(D10=1,E10/0.53,IF(D10=2,E10/0.36,IF(D10=3,E10/0.091,IF(D10=4,E10/0.015,E10/0.004)))) -> 0.044 | G10: =ROUND(F10,4) -> 0.044 | H10: =G10*10000 -> 440 | I10: 417
A11: 101001 | B11: Kim Tra | C11: =VLOOKUP(B11,[2]英雄技能!$D:$E,2,0) -> #N/A | D11: 4 | E11: 0.00066 | F11: =IF(D11=1,E11/0.53,IF(D11=2,E11/0.36,IF(D11=3,E11/0.091,IF(D11=4,E11/0.015,E11/0.004)))) -> 0.044 | G11: =ROUND(F11,4) -> 0.044 | H11: =G11*10000 -> 440 | I11: 417
A12: 101101 | B12: Văn Trọng | C12: =VLOOKUP(B12,[2]英雄技能!$D:$E,2,0) -> #N/A | D12: 4 | E12: 0.00066 | F12: =IF(D12=1,E12/0.53,IF(D12=2,E12/0.36,IF(D12=3,E12/0.091,IF(D12=4,E12/0.015,E12/0.004)))) -> 0.044 | G12: =ROUND(F12,4) -> 0.044 | H12: =G12*10000 -> 440 | I12: 417
A13: 101201 | B13: Hoàng Phi Hổ | C13: =VLOOKUP(B13,[2]英雄技能!$D:$E,2,0) -> #N/A | D13: 4 | E13: 0.00066 | F13: =IF(D13=1,E13/0.53,IF(D13=2,E13/0.36,IF(D13=3,E13/0.091,IF(D13=4,E13/0.015,E13/0.004)))) -> 0.044 | G13: =ROUND(F13,4) -> 0.044 | H13: =G13*10000 -> 440 | I13: 417
A14: 101301 | B14: Cơ Phát | C14: =VLOOKUP(B14,[2]英雄技能!$D:$E,2,0) -> #N/A | D14: 4 | E14: 0.00066 | F14: =IF(D14=1,E14/0.53,IF(D14=2,E14/0.36,IF(D14=3,E14/0.091,IF(D14=4,E14/0.015,E14/0.004)))) -> 0.044 | G14: =ROUND(F14,4) -> 0.044 | H14: =G14*10000 -> 440 | I14: 417
A15: 101401 | B15: Dương Tiễn | C15: =VLOOKUP(B15,[2]英雄技能!$D:$E,2,0) -> #N/A | D15: 5 | E15: 0.00011 | F15: =IF(D15=1,E15/0.53,IF(D15=2,E15/0.36,IF(D15=3,E15/0.091,IF(D15=4,E15/0.015,E15/0.004)))) -> 0.0275 | G15: =ROUND(F15,4) -> 0.0275 | H15: =G15*10000 -> 275 | I15: =H15 -> 275
A16: 101501 | B16: Đặng Thiền Ngọc | C16: =VLOOKUP(B16,[2]英雄技能!$D:$E,2,0) -> #N/A | D16: 5 | E16: 0.00023 | F16: =IF(D16=1,E16/0.53,IF(D16=2,E16/0.36,IF(D16=3,E16/0.091,IF(D16=4,E16/0.015,E16/0.004)))) -> 0.0575 | G16: =ROUND(F16,4) -> 0.0575 | H16: =G16*10000 -> 575 | I16: =H16 -> 575
A17: 101601 | B17: Hằng Nga | C17: =VLOOKUP(B17,[2]英雄技能!$D:$E,2,0) -> #N/A | D17: 5 | E17: 3e-05 | F17: =IF(D17=1,E17/0.53,IF(D17=2,E17/0.36,IF(D17=3,E17/0.091,IF(D17=4,E17/0.015,E17/0.004)))) -> 0.0075 | G17: =ROUND(F17,4) -> 0.0075 | H17: =G17*10000 -> 75 | I17: =H17 -> 75
A18: 101701 | B18: Thân không báo | C18: =VLOOKUP(B18,[2]英雄技能!$D:$E,2,0) -> #N/A | D18: 5 | E18: 3e-05 | F18: =IF(D18=1,E18/0.53,IF(D18=2,E18/0.36,IF(D18=3,E18/0.091,IF(D18=4,E18/0.015,E18/0.004)))) -> 0.0075 | G18: =ROUND(F18,4) -> 0.0075 | H18: =G18*10000 -> 75 | I18: =H18 -> 75
A19: 101801 | B19: Hậu Nghệ | C19: =VLOOKUP(B19,[2]英雄技能!$D:$E,2,0) -> #N/A | D19: 5 | E19: 0.00011 | F19: =IF(D19=1,E19/0.53,IF(D19=2,E19/0.36,IF(D19=3,E19/0.091,IF(D19=4,E19/0.015,E19/0.004)))) -> 0.0275 | G19: =ROUND(F19,4) -> 0.0275 | H19: =G19*10000 -> 275 | I19: =H19 -> 275
A20: 101901 | B20: Lý Tĩnh | C20: =VLOOKUP(B20,[2]英雄技能!$D:$E,2,0) -> #N/A | D20: 5 | E20: 3e-05 | F20: =IF(D20=1,E20/0.53,IF(D20=2,E20/0.36,IF(D20=3,E20/0.091,IF(D20=4,E20/0.015,E20/0.004)))) -> 0.0075 | G20: =ROUND(F20,4) -> 0.0075 | H20: =G20*10000 -> 75 | I20: =H20 -> 75
A21: 102001 | B21: Na Tra | C21: =VLOOKUP(B21,[2]英雄技能!$D:$E,2,0) -> #N/A | D21: 5 | E21: 3e-05 | F21: =IF(D21=1,E21/0.53,IF(D21=2,E21/0.36,IF(D21=3,E21/0.091,IF(D21=4,E21/0.015,E21/0.004)))) -> 0.0075 | G21: =ROUND(F21,4) -> 0.0075 | H21: =G21*10000 -> 75 | I21: =H21 -> 75
A22: 102101 | B22: Khương Tử Nha | C22: =VLOOKUP(B22,[2]英雄技能!$D:$E,2,0) -> #N/A | D22: 5 | E22: 0.00011 | F22: =IF(D22=1,E22/0.53,IF(D22=2,E22/0.36,IF(D22=3,E22/0.091,IF(D22=4,E22/0.015,E22/0.004)))) -> 0.0275 | G22: =ROUND(F22,4) -> 0.0275 | H22: =G22*10000 -> 275 | I22: =H22 -> 275
A23: 102201 | B23: Lôi Chấn Tử | C23: =VLOOKUP(B23,[2]英雄技能!$D:$E,2,0) -> #N/A | D23: 5 | E23: 0.00023 | F23: =IF(D23=1,E23/0.53,IF(D23=2,E23/0.36,IF(D23=3,E23/0.091,IF(D23=4,E23/0.015,E23/0.004)))) -> 0.0575 | G23: =ROUND(F23,4) -> 0.0575 | H23: =G23*10000 -> 575 | I23: =H23 -> 575
A24: 200101 | B24: Tiên đồng | C24: =VLOOKUP(B24,[2]英雄技能!$D:$E,2,0) -> #N/A | D24: 1 | E24: 0.17821 | F24: =IF(D24=1,E24/0.53,IF(D24=2,E24/0.36,IF(D24=3,E24/0.091,IF(D24=4,E24/0.015,E24/0.004)))) -> 0.33624528 | G24: =ROUND(F24,4) -> 0.3362 | H24: =G24*10000 -> 3362 | I24: 3333
A25: 200201 | B25: Nhật du thần | C25: =VLOOKUP(B25,[2]英雄技能!$D:$E,2,0) -> #N/A | D25: 2 | E25: 0.06 | F25: =IF(D25=1,E25/0.53,IF(D25=2,E25/0.36,IF(D25=3,E25/0.091,IF(D25=4,E25/0.015,E25/0.004)))) -> 0.16666667 | G25: =ROUND(F25,4) -> 0.1667 | H25: =G25*10000 -> 1667 | I25: 1667
A26: 200301 | B26: Thần dạ du | C26: =VLOOKUP(B26,[2]英雄技能!$D:$E,2,0) -> #N/A | D26: 2 | E26: 0.06 | F26: =IF(D26=1,E26/0.53,IF(D26=2,E26/0.36,IF(D26=3,E26/0.091,IF(D26=4,E26/0.015,E26/0.004)))) -> 0.16666667 | G26: =ROUND(F26,4) -> 0.1667 | H26: =G26*10000 -> 1667 | I26: 1667
A27: 200401 | B27: Kim Đồng | C27: =VLOOKUP(B27,[2]英雄技能!$D:$E,2,0) -> #N/A | D27: 3 | E27: 0.00535 | F27: =IF(D27=1,E27/0.53,IF(D27=2,E27/0.36,IF(D27=3,E27/0.091,IF(D27=4,E27/0.015,E27/0.004)))) -> 0.058791209 | G27: =ROUND(F27,4) -> 0.0588 | H27: =G27*10000 -> 588 | I27: 625
A28: 200501 | B28: Ngọc nữ | C28: =VLOOKUP(B28,[2]英雄技能!$D:$E,2,0) -> #N/A | D28: 3 | E28: 0.00535 | F28: =IF(D28=1,E28/0.53,IF(D28=2,E28/0.36,IF(D28=3,E28/0.091,IF(D28=4,E28/0.015,E28/0.004)))) -> 0.058791209 | G28: =ROUND(F28,4) -> 0.0588 | H28: =G28*10000 -> 588 | I28: 625
A29: 200601 | B29: Thanh tiêu | C29: =VLOOKUP(B29,[2]英雄技能!$D:$E,2,0) -> #N/A | D29: 3 | E29: 0.00535 | F29: =IF(D29=1,E29/0.53,IF(D29=2,E29/0.36,IF(D29=3,E29/0.091,IF(D29=4,E29/0.015,E29/0.004)))) -> 0.058791209 | G29: =ROUND(F29,4) -> 0.0588 | H29: =G29*10000 -> 588 | I29: 625
A30: 200701 | B30: Long Cát công chúa | C30: =VLOOKUP(B30,[2]英雄技能!$D:$E,2,0) -> #N/A | D30: 3 | E30: 0.00535 | F30: =IF(D30=1,E30/0.53,IF(D30=2,E30/0.36,IF(D30=3,E30/0.091,IF(D30=4,E30/0.015,E30/0.004)))) -> 0.058791209 | G30: =ROUND(F30,4) -> 0.0588 | H30: =G30*10000 -> 588 | I30: 625
A31: 200801 | B31: Bạch long | C31: =VLOOKUP(B31,[2]英雄技能!$D:$E,2,0) -> #N/A | D31: 3 | E31: 0.00535 | F31: =IF(D31=1,E31/0.53,IF(D31=2,E31/0.36,IF(D31=3,E31/0.091,IF(D31=4,E31/0.015,E31/0.004)))) -> 0.058791209 | G31: =ROUND(F31,4) -> 0.0588 | H31: =G31*10000 -> 588 | I31: 625
A32: 200901 | B32: Thái Bạch Kim Tinh | C32: =VLOOKUP(B32,[2]英雄技能!$D:$E,2,0) -> #N/A | D32: 4 | E32: 0.00066 | F32: =IF(D32=1,E32/0.53,IF(D32=2,E32/0.36,IF(D32=3,E32/0.091,IF(D32=4,E32/0.015,E32/0.004)))) -> 0.044 | G32: =ROUND(F32,4) -> 0.044 | H32: =G32*10000 -> 440 | I32: 417
A33: 201001 | B33: Nguyệt lão | C33: =VLOOKUP(B33,[2]英雄技能!$D:$E,2,0) -> #N/A | D33: 4 | E33: 0.00066 | F33: =IF(D33=1,E33/0.53,IF(D33=2,E33/0.36,IF(D33=3,E33/0.091,IF(D33=4,E33/0.015,E33/0.004)))) -> 0.044 | G33: =ROUND(F33,4) -> 0.044 | H33: =G33*10000 -> 440 | I33: 417
A34: 201101 | B34: Chức Nữ | C34: =VLOOKUP(B34,[2]英雄技能!$D:$E,2,0) -> #N/A | D34: 4 | E34: 0.00066 | F34: =IF(D34=1,E34/0.53,IF(D34=2,E34/0.36,IF(D34=3,E34/0.091,IF(D34=4,E34/0.015,E34/0.004)))) -> 0.044 | G34: =ROUND(F34,4) -> 0.044 | H34: =G34*10000 -> 440 | I34: 417
A35: 201201 | B35: Hà Bá | C35: =VLOOKUP(B35,[2]英雄技能!$D:$E,2,0) -> #N/A | D35: 4 | E35: 0.00066 | F35: =IF(D35=1,E35/0.53,IF(D35=2,E35/0.36,IF(D35=3,E35/0.091,IF(D35=4,E35/0.015,E35/0.004)))) -> 0.044 | G35: =ROUND(F35,4) -> 0.044 | H35: =G35*10000 -> 440 | I35: 417
A36: 201301 | B36: Vũ Sư | C36: =VLOOKUP(B36,[2]英雄技能!$D:$E,2,0) -> #N/A | D36: 4 | E36: 0.00066 | F36: =IF(D36=1,E36/0.53,IF(D36=2,E36/0.36,IF(D36=3,E36/0.091,IF(D36=4,E36/0.015,E36/0.004)))) -> 0.044 | G36: =ROUND(F36,4) -> 0.044 | H36: =G36*10000 -> 440 | I36: 417
A37: 201401 | B37: Quyển Liêm Đại Tướng | C37: =VLOOKUP(B37,[2]英雄技能!$D:$E,2,0) -> #N/A | D37: 5 | E37: 0.00023 | F37: =IF(D37=1,E37/0.53,IF(D37=2,E37/0.36,IF(D37=3,E37/0.091,IF(D37=4,E37/0.015,E37/0.004)))) -> 0.0575 | G37: =ROUND(F37,4) -> 0.0575 | H37: =G37*10000 -> 575 | I37: =H37 -> 575
A38: 201501 | B38: Thiên Bồng nguyên soái | C38: =VLOOKUP(B38,[2]英雄技能!$D:$E,2,0) -> #N/A | D38: 5 | E38: 3e-05 | F38: =IF(D38=1,E38/0.53,IF(D38=2,E38/0.36,IF(D38=3,E38/0.091,IF(D38=4,E38/0.015,E38/0.004)))) -> 0.0075 | G38: =ROUND(F38,4) -> 0.0075 | H38: =G38*10000 -> 75 | I38: =H38 -> 75
A39: 201601 | B39: Nam Cực Tiên Ông | C39: =VLOOKUP(B39,[2]英雄技能!$D:$E,2,0) -> #N/A | D39: 5 | E39: 0.00011 | F39: =IF(D39=1,E39/0.53,IF(D39=2,E39/0.36,IF(D39=3,E39/0.091,IF(D39=4,E39/0.015,E39/0.004)))) -> 0.0275 | G39: =ROUND(F39,4) -> 0.0275 | H39: =G39*10000 -> 275 | I39: =H39 -> 275
A40: 201701 | B40: Tài thần | C40: =VLOOKUP(B40,[2]英雄技能!$D:$E,2,0) -> #N/A | D40: 5 | E40: 0.00023 | F40: =IF(D40=1,E40/0.53,IF(D40=2,E40/0.36,IF(D40=3,E40/0.091,IF(D40=4,E40/0.015,E40/0.004)))) -> 0.0575 | G40: =ROUND(F40,4) -> 0.0575 | H40: =G40*10000 -> 575 | I40: =H40 -> 575
...

Sheet Sheet(友情召唤概率)
A1: 英雄ID | B1: 名字 | C1: 闪烁之光角色 | D1: 星级 | E1: 概率 | F1: 子包概率 | G1: 取后四位 | H1: 万分比计算 | I1: 修正
A2: 100201 | B2: 医师 | C2: =VLOOKUP(B2,[2]英雄技能!$D:$E,2,0) -> #N/A | D2: 2 | E2: 0.05916 | F2: =IF(D2=2,E2/0.355,IF(D2=3,E2/0.5,IF(D2=4,E2/0.135,E2/0.01))) -> 0.16664789 | G2: =ROUND(F2,4) -> 0.1666 | H2: =G2*10000 -> 1666 | I2: 1667
A3: 100301 | B3: 长弓手 | C3: =VLOOKUP(B3,[2]英雄技能!$D:$E,2,0) -> #N/A | D3: 2 | E3: 0.05916 | F3: =IF(D3=2,E3/0.355,IF(D3=3,E3/0.5,IF(D3=4,E3/0.135,E3/0.01))) -> 0.16664789 | G3: =ROUND(F3,4) -> 0.1666 | H3: =G3*10000 -> 1666 | I3: 1667
A4: 100401 | B4: 金吾卫 | C4: =VLOOKUP(B4,[2]英雄技能!$D:$E,2,0) -> #N/A | D4: 3 | E4: 0.02941 | F4: =IF(D4=2,E4/0.355,IF(D4=3,E4/0.5,IF(D4=4,E4/0.135,E4/0.01))) -> 0.05882 | G4: =ROUND(F4,4) -> 0.0588 | H4: =G4*10000 -> 588 | I4: 625
A5: 100501 | B5: 殿前禁卫 | C5: =VLOOKUP(B5,[2]英雄技能!$D:$E,2,0) -> #N/A | D5: 3 | E5: 0.02941 | F5: =IF(D5=2,E5/0.355,IF(D5=3,E5/0.5,IF(D5=4,E5/0.135,E5/0.01))) -> 0.05882 | G5: =ROUND(F5,4) -> 0.0588 | H5: =G5*10000 -> 588 | I5: 625
A6: 100601 | B6: 虎豹骑 | C6: =VLOOKUP(B6,[2]英雄技能!$D:$E,2,0) -> #N/A | D6: 3 | E6: 0.02941 | F6: =IF(D6=2,E6/0.355,IF(D6=3,E6/0.5,IF(D6=4,E6/0.135,E6/0.01))) -> 0.05882 | G6: =ROUND(F6,4) -> 0.0588 | H6: =G6*10000 -> 588 | I6: 625
A7: 100701 | B7: 燕赤侠 | C7: =VLOOKUP(B7,[2]英雄技能!$D:$E,2,0) -> #N/A | D7: 3 | E7: 0.02941 | F7: =IF(D7=2,E7/0.355,IF(D7=3,E7/0.5,IF(D7=4,E7/0.135,E7/0.01))) -> 0.05882 | G7: =ROUND(F7,4) -> 0.0588 | H7: =G7*10000 -> 588 | I7: 625
A8: 100801 | B8: 木吒 | C8: =VLOOKUP(B8,[2]英雄技能!$D:$E,2,0) -> #N/A | D8: 3 | E8: 0.02941 | F8: =IF(D8=2,E8/0.355,IF(D8=3,E8/0.5,IF(D8=4,E8/0.135,E8/0.01))) -> 0.05882 | G8: =ROUND(F8,4) -> 0.0588 | H8: =G8*10000 -> 588 | I8: 625
A9: 100901 | B9: 纣王 | C9: =VLOOKUP(B9,[2]英雄技能!$D:$E,2,0) -> #N/A | D9: 4 | E9: 0.006 | F9: =IF(D9=2,E9/0.355,IF(D9=3,E9/0.5,IF(D9=4,E9/0.135,E9/0.01))) -> 0.044444444 | G9: =ROUND(F9,4) -> 0.0444 | H9: =G9*10000 -> 444 | I9: 417
A10: 101001 | B10: 金吒 | C10: =VLOOKUP(B10,[2]英雄技能!$D:$E,2,0) -> #N/A | D10: 4 | E10: 0.006 | F10: =IF(D10=2,E10/0.355,IF(D10=3,E10/0.5,IF(D10=4,E10/0.135,E10/0.01))) -> 0.044444444 | G10: =ROUND(F10,4) -> 0.0444 | H10: =G10*10000 -> 444 | I10: 417
A11: 101101 | B11: 闻仲 | C11: =VLOOKUP(B11,[2]英雄技能!$D:$E,2,0) -> #N/A | D11: 4 | E11: 0.006 | F11: =IF(D11=2,E11/0.355,IF(D11=3,E11/0.5,IF(D11=4,E11/0.135,E11/0.01))) -> 0.044444444 | G11: =ROUND(F11,4) -> 0.0444 | H11: =G11*10000 -> 444 | I11: 417
A12: 101201 | B12: 黄飞虎 | C12: =VLOOKUP(B12,[2]英雄技能!$D:$E,2,0) -> #N/A | D12: 4 | E12: 0.006 | F12: =IF(D12=2,E12/0.355,IF(D12=3,E12/0.5,IF(D12=4,E12/0.135,E12/0.01))) -> 0.044444444 | G12: =ROUND(F12,4) -> 0.0444 | H12: =G12*10000 -> 444 | I12: 417
A13: 101301 | B13: 姬发 | C13: =VLOOKUP(B13,[2]英雄技能!$D:$E,2,0) -> #N/A | D13: 4 | E13: 0.006 | F13: =IF(D13=2,E13/0.355,IF(D13=3,E13/0.5,IF(D13=4,E13/0.135,E13/0.01))) -> 0.044444444 | G13: =ROUND(F13,4) -> 0.0444 | H13: =G13*10000 -> 444 | I13: 417
A14: 101401 | B14: 杨戬 | C14: =VLOOKUP(B14,[2]英雄技能!$D:$E,2,0) -> #N/A | D14: 5 | E14: 0.00014 | F14: =IF(D14=2,E14/0.355,IF(D14=3,E14/0.5,IF(D14=4,E14/0.135,E14/0.01))) -> 0.014 | G14: =ROUND(F14,4) -> 0.014 | H14: =G14*10000 -> 140 | I14: =IF(OR(H14=140,H14=690,H14=340),H14+10,H14) -> 150
A15: 101501 | B15: 邓婵玉 | C15: =VLOOKUP(B15,[2]英雄技能!$D:$E,2,0) -> #N/A | D15: 5 | E15: 0.00069 | F15: =IF(D15=2,E15/0.355,IF(D15=3,E15/0.5,IF(D15=4,E15/0.135,E15/0.01))) -> 0.069 | G15: =ROUND(F15,4) -> 0.069 | H15: =G15*10000 -> 690 | I15: =IF(OR(H15=140,H15=690,H15=340),H15+10,H15) -> 700
A16: 101601 | B16: 嫦娥 | C16: =VLOOKUP(B16,[2]英雄技能!$D:$E,2,0) -> #N/A | D16: 5 | E16: 6e-05 | F16: =IF(D16=2,E16/0.355,IF(D16=3,E16/0.5,IF(D16=4,E16/0.135,E16/0.01))) -> 0.006 | G16: =ROUND(F16,4) -> 0.006 | H16: =G16*10000 -> 60 | I16: =IF(OR(H16=140,H16=690,H16=340),H16+10,H16) -> 60
A17: 101701 | B17: 申空豹 | C17: =VLOOKUP(B17,[2]英雄技能!$D:$E,2,0) -> #N/A | D17: 5 | E17: 6e-05 | F17: =IF(D17=2,E17/0.355,IF(D17=3,E17/0.5,IF(D17=4,E17/0.135,E17/0.01))) -> 0.006 | G17: =ROUND(F17,4) -> 0.006 | H17: =G17*10000 -> 60 | I17: =IF(OR(H17=140,H17=690,H17=340),H17+10,H17) -> 60
A18: 101801 | B18: 后羿 | C18: =VLOOKUP(B18,[2]英雄技能!$D:$E,2,0) -> #N/A | D18: 5 | E18: 0.00014 | F18: =IF(D18=2,E18/0.355,IF(D18=3,E18/0.5,IF(D18=4,E18/0.135,E18/0.01))) -> 0.014 | G18: =ROUND(F18,4) -> 0.014 | H18: =G18*10000 -> 140 | I18: =IF(OR(H18=140,H18=690,H18=340),H18+10,H18) -> 150
A19: 101901 | B19: 李靖 | C19: =VLOOKUP(B19,[2]英雄技能!$D:$E,2,0) -> #N/A | D19: 5 | E19: 6e-05 | F19: =IF(D19=2,E19/0.355,IF(D19=3,E19/0.5,IF(D19=4,E19/0.135,E19/0.01))) -> 0.006 | G19: =ROUND(F19,4) -> 0.006 | H19: =G19*10000 -> 60 | I19: =IF(OR(H19=140,H19=690,H19=340),H19+10,H19) -> 60
A20: 102001 | B20: 哪吒 | C20: =VLOOKUP(B20,[2]英雄技能!$D:$E,2,0) -> #N/A | D20: 5 | E20: 6e-05 | F20: =IF(D20=2,E20/0.355,IF(D20=3,E20/0.5,IF(D20=4,E20/0.135,E20/0.01))) -> 0.006 | G20: =ROUND(F20,4) -> 0.006 | H20: =G20*10000 -> 60 | I20: =IF(OR(H20=140,H20=690,H20=340),H20+10,H20) -> 60
A21: 102101 | B21: 姜子牙 | C21: =VLOOKUP(B21,[2]英雄技能!$D:$E,2,0) -> #N/A | D21: 5 | E21: 0.00014 | F21: =IF(D21=2,E21/0.355,IF(D21=3,E21/0.5,IF(D21=4,E21/0.135,E21/0.01))) -> 0.014 | G21: =ROUND(F21,4) -> 0.014 | H21: =G21*10000 -> 140 | I21: =IF(OR(H21=140,H21=690,H21=340),H21+10,H21) -> 150
A22: 102201 | B22: 雷震子 | C22: =VLOOKUP(B22,[2]英雄技能!$D:$E,2,0) -> #N/A | D22: 5 | E22: 0.00069 | F22: =IF(D22=2,E22/0.355,IF(D22=3,E22/0.5,IF(D22=4,E22/0.135,E22/0.01))) -> 0.069 | G22: =ROUND(F22,4) -> 0.069 | H22: =G22*10000 -> 690 | I22: =IF(OR(H22=140,H22=690,H22=340),H22+10,H22) -> 700
A23: 200201 | B23: 日游神 | C23: =VLOOKUP(B23,[2]英雄技能!$D:$E,2,0) -> #N/A | D23: 2 | E23: 0.05917 | F23: =IF(D23=2,E23/0.355,IF(D23=3,E23/0.5,IF(D23=4,E23/0.135,E23/0.01))) -> 0.16667606 | G23: =ROUND(F23,4) -> 0.1667 | H23: 1667 | I23: 1667
A24: 200301 | B24: 夜游神 | C24: =VLOOKUP(B24,[2]英雄技能!$D:$E,2,0) -> #N/A | D24: 2 | E24: 0.05917 | F24: =IF(D24=2,E24/0.355,IF(D24=3,E24/0.5,IF(D24=4,E24/0.135,E24/0.01))) -> 0.16667606 | G24: =ROUND(F24,4) -> 0.1667 | H24: 1667 | I24: 1667
A25: 200401 | B25: 金童 | C25: =VLOOKUP(B25,[2]英雄技能!$D:$E,2,0) -> #N/A | D25: 3 | E25: 0.02941 | F25: =IF(D25=2,E25/0.355,IF(D25=3,E25/0.5,IF(D25=4,E25/0.135,E25/0.01))) -> 0.05882 | G25: =ROUND(F25,4) -> 0.0588 | H25: =G25*10000 -> 588 | I25: 625
A26: 200501 | B26: 玉女 | C26: =VLOOKUP(B26,[2]英雄技能!$D:$E,2,0) -> #N/A | D26: 3 | E26: 0.02941 | F26: =IF(D26=2,E26/0.355,IF(D26=3,E26/0.5,IF(D26=4,E26/0.135,E26/0.01))) -> 0.05882 | G26: =ROUND(F26,4) -> 0.0588 | H26: =G26*10000 -> 588 | I26: 625
A27: 200601 | B27: 青宵 | C27: =VLOOKUP(B27,[2]英雄技能!$D:$E,2,0) -> #N/A | D27: 3 | E27: 0.02941 | F27: =IF(D27=2,E27/0.355,IF(D27=3,E27/0.5,IF(D27=4,E27/0.135,E27/0.01))) -> 0.05882 | G27: =ROUND(F27,4) -> 0.0588 | H27: =G27*10000 -> 588 | I27: 625
A28: 200701 | B28: 龙吉公主 | C28: =VLOOKUP(B28,[2]英雄技能!$D:$E,2,0) -> #N/A | D28: 3 | E28: 0.02941 | F28: =IF(D28=2,E28/0.355,IF(D28=3,E28/0.5,IF(D28=4,E28/0.135,E28/0.01))) -> 0.05882 | G28: =ROUND(F28,4) -> 0.0588 | H28: =G28*10000 -> 588 | I28: 625
A29: 200801 | B29: 白龙 | C29: =VLOOKUP(B29,[2]英雄技能!$D:$E,2,0) -> #N/A | D29: 3 | E29: 0.02941 | F29: =IF(D29=2,E29/0.355,IF(D29=3,E29/0.5,IF(D29=4,E29/0.135,E29/0.01))) -> 0.05882 | G29: =ROUND(F29,4) -> 0.0588 | H29: =G29*10000 -> 588 | I29: 625
A30: 200901 | B30: 太白金星 | C30: =VLOOKUP(B30,[2]英雄技能!$D:$E,2,0) -> #N/A | D30: 4 | E30: 0.006 | F30: =IF(D30=2,E30/0.355,IF(D30=3,E30/0.5,IF(D30=4,E30/0.135,E30/0.01))) -> 0.044444444 | G30: =ROUND(F30,4) -> 0.0444 | H30: =G30*10000 -> 444 | I30: 417
A31: 201001 | B31: 月老 | C31: =VLOOKUP(B31,[2]英雄技能!$D:$E,2,0) -> #N/A | D31: 4 | E31: 0.006 | F31: =IF(D31=2,E31/0.355,IF(D31=3,E31/0.5,IF(D31=4,E31/0.135,E31/0.01))) -> 0.044444444 | G31: =ROUND(F31,4) -> 0.0444 | H31: =G31*10000 -> 444 | I31: 417
A32: 201101 | B32: 织女 | C32: =VLOOKUP(B32,[2]英雄技能!$D:$E,2,0) -> #N/A | D32: 4 | E32: 0.006 | F32: =IF(D32=2,E32/0.355,IF(D32=3,E32/0.5,IF(D32=4,E32/0.135,E32/0.01))) -> 0.044444444 | G32: =ROUND(F32,4) -> 0.0444 | H32: =G32*10000 -> 444 | I32: 417
A33: 201201 | B33: 河伯 | C33: =VLOOKUP(B33,[2]英雄技能!$D:$E,2,0) -> #N/A | D33: 4 | E33: 0.006 | F33: =IF(D33=2,E33/0.355,IF(D33=3,E33/0.5,IF(D33=4,E33/0.135,E33/0.01))) -> 0.044444444 | G33: =ROUND(F33,4) -> 0.0444 | H33: =G33*10000 -> 444 | I33: 417
A34: 201301 | B34: 雨师 | C34: =VLOOKUP(B34,[2]英雄技能!$D:$E,2,0) -> #N/A | D34: 4 | E34: 0.006 | F34: =IF(D34=2,E34/0.355,IF(D34=3,E34/0.5,IF(D34=4,E34/0.135,E34/0.01))) -> 0.044444444 | G34: =ROUND(F34,4) -> 0.0444 | H34: =G34*10000 -> 444 | I34: 417
A35: 201401 | B35: 卷帘大将 | C35: =VLOOKUP(B35,[2]英雄技能!$D:$E,2,0) -> #N/A | D35: 5 | E35: 0.00069 | F35: =IF(D35=2,E35/0.355,IF(D35=3,E35/0.5,IF(D35=4,E35/0.135,E35/0.01))) -> 0.069 | G35: =ROUND(F35,4) -> 0.069 | H35: =G35*10000 -> 690 | I35: =IF(OR(H35=140,H35=690,H35=340),H35+10,H35) -> 700
A36: 201501 | B36: 天蓬元帅 | C36: =VLOOKUP(B36,[2]英雄技能!$D:$E,2,0) -> #N/A | D36: 5 | E36: 6e-05 | F36: =IF(D36=2,E36/0.355,IF(D36=3,E36/0.5,IF(D36=4,E36/0.135,E36/0.01))) -> 0.006 | G36: =ROUND(F36,4) -> 0.006 | H36: =G36*10000 -> 60 | I36: =IF(OR(H36=140,H36=690,H36=340),H36+10,H36) -> 60
A37: 201601 | B37: 南极仙翁 | C37: =VLOOKUP(B37,[2]英雄技能!$D:$E,2,0) -> #N/A | D37: 5 | E37: 0.00014 | F37: =IF(D37=2,E37/0.355,IF(D37=3,E37/0.5,IF(D37=4,E37/0.135,E37/0.01))) -> 0.014 | G37: =ROUND(F37,4) -> 0.014 | H37: =G37*10000 -> 140 | I37: =IF(OR(H37=140,H37=690,H37=340),H37+10,H37) -> 150
A38: 201701 | B38: 财神 | C38: =VLOOKUP(B38,[2]英雄技能!$D:$E,2,0) -> #N/A | D38: 5 | E38: 0.00069 | F38: =IF(D38=2,E38/0.355,IF(D38=3,E38/0.5,IF(D38=4,E38/0.135,E38/0.01))) -> 0.069 | G38: =ROUND(F38,4) -> 0.069 | H38: =G38*10000 -> 690 | I38: =IF(OR(H38=140,H38=690,H38=340),H38+10,H38) -> 700
A39: 201801 | B39: 斗战胜佛 | C39: =VLOOKUP(B39,[2]英雄技能!$D:$E,2,0) -> #N/A | D39: 5 | E39: 6e-05 | F39: =IF(D39=2,E39/0.355,IF(D39=3,E39/0.5,IF(D39=4,E39/0.135,E39/0.01))) -> 0.006 | G39: =ROUND(F39,4) -> 0.006 | H39: =G39*10000 -> 60 | I39: =IF(OR(H39=140,H39=690,H39=340),H39+10,H39) -> 60
A40: 201901 | B40: 太乙真人 | C40: =VLOOKUP(B40,[2]英雄技能!$D:$E,2,0) -> #N/A | D40: 5 | E40: 6e-05 | F40: =IF(D40=2,E40/0.355,IF(D40=3,E40/0.5,IF(D40=4,E40/0.135,E40/0.01))) -> 0.006 | G40: =ROUND(F40,4) -> 0.006 | H40: =G40*10000 -> 60 | I40: =IF(OR(H40=140,H40=690,H40=340),H40+10,H40) -> 60
...

Sheet Sheet(高级召唤概率)
A1: 英雄ID | B1: 名字 | C1: 闪烁之光角色 | D1: 星级 | E1: 概率 | F1: 子包概率 | G1: 取后四位 | H1: 万分比计算 | I1: 修正
A2: 100401 | B2: 金吾卫 | C2: =VLOOKUP(B2,[2]英雄技能!$D:$E,2,0) -> #N/A | D2: 3 | E2: 0.047 | F2: =IF(D2=3,E2/0.8,IF(D2=4,E2/0.15,E2/0.05)) -> 0.05875 | G2: =ROUND(F2,4) -> 0.0588 | H2: =G2*10000 -> 588 | I2: 1500
A3: 100501 | B3: 殿前禁卫 | C3: =VLOOKUP(B3,[2]英雄技能!$D:$E,2,0) -> #N/A | D3: 3 | E3: 0.047 | F3: =IF(D3=3,E3/0.8,IF(D3=4,E3/0.15,E3/0.05)) -> 0.05875 | G3: =ROUND(F3,4) -> 0.0588 | H3: =G3*10000 -> 588 | I3: 1500
A4: 100601 | B4: 虎豹骑 | C4: =VLOOKUP(B4,[2]英雄技能!$D:$E,2,0) -> #N/A | D4: 3 | E4: 0.047 | F4: =IF(D4=3,E4/0.8,IF(D4=4,E4/0.15,E4/0.05)) -> 0.05875 | G4: =ROUND(F4,4) -> 0.0588 | H4: =G4*10000 -> 588 | I4: 1500
A5: 100701 | B5: 燕赤侠 | C5: =VLOOKUP(B5,[2]英雄技能!$D:$E,2,0) -> #N/A | D5: 3 | E5: 0.047 | F5: =IF(D5=3,E5/0.8,IF(D5=4,E5/0.15,E5/0.05)) -> 0.05875 | G5: =ROUND(F5,4) -> 0.0588 | H5: =G5*10000 -> 588 | I5: 1500
A6: 100801 | B6: 木吒 | C6: =VLOOKUP(B6,[2]英雄技能!$D:$E,2,0) -> #N/A | D6: 3 | E6: 0.047 | F6: =IF(D6=3,E6/0.8,IF(D6=4,E6/0.15,E6/0.05)) -> 0.05875 | G6: =ROUND(F6,4) -> 0.0588 | H6: =G6*10000 -> 588 | I6: 1500
A7: 100901 | B7: 纣王 | C7: =VLOOKUP(B7,[2]英雄技能!$D:$E,2,0) -> #N/A | D7: 4 | E7: 0.00667 | F7: =IF(D7=3,E7/0.8,IF(D7=4,E7/0.15,E7/0.05)) -> 0.044466667 | G7: =ROUND(F7,4) -> 0.0445 | H7: =G7*10000 -> 445 | I7: 188
A8: 101001 | B8: 金吒 | C8: =VLOOKUP(B8,[2]英雄技能!$D:$E,2,0) -> #N/A | D8: 4 | E8: 0.00667 | F8: =IF(D8=3,E8/0.8,IF(D8=4,E8/0.15,E8/0.05)) -> 0.044466667 | G8: =ROUND(F8,4) -> 0.0445 | H8: =G8*10000 -> 445 | I8: 188
A9: 101101 | B9: 闻仲 | C9: =VLOOKUP(B9,[2]英雄技能!$D:$E,2,0) -> #N/A | D9: 4 | E9: 0.00667 | F9: =IF(D9=3,E9/0.8,IF(D9=4,E9/0.15,E9/0.05)) -> 0.044466667 | G9: =ROUND(F9,4) -> 0.0445 | H9: =G9*10000 -> 445 | I9: 188
A10: 101201 | B10: 黄飞虎 | C10: =VLOOKUP(B10,[2]英雄技能!$D:$E,2,0) -> #N/A | D10: 4 | E10: 0.00667 | F10: =IF(D10=3,E10/0.8,IF(D10=4,E10/0.15,E10/0.05)) -> 0.044466667 | G10: =ROUND(F10,4) -> 0.0445 | H10: =G10*10000 -> 445 | I10: 188 | R10: 24000
A11: 101301 | B11: 姬发 | C11: =VLOOKUP(B11,[2]英雄技能!$D:$E,2,0) -> #N/A | D11: 4 | E11: 0.00667 | F11: =IF(D11=3,E11/0.8,IF(D11=4,E11/0.15,E11/0.05)) -> 0.044466667 | G11: =ROUND(F11,4) -> 0.0445 | H11: =G11*10000 -> 445 | I11: 188 | R11: =30000*0.15 -> 4500
A12: 101401 | B12: 杨戬 | C12: =VLOOKUP(B12,[2]英雄技能!$D:$E,2,0) -> #N/A | D12: 5 | E12: 0.00074 | F12: =IF(D12=3,E12/0.8,IF(D12=4,E12/0.15,E12/0.05)) -> 0.0148 | G12: =ROUND(F12,4) -> 0.0148 | H12: =G12*10000 -> 148 | I12: 30
A13: 101501 | B13: 邓婵玉 | C13: =VLOOKUP(B13,[2]英雄技能!$D:$E,2,0) -> #N/A | D13: 5 | E13: 0.0037 | F13: =IF(D13=3,E13/0.8,IF(D13=4,E13/0.15,E13/0.05)) -> 0.074 | G13: =ROUND(F13,4) -> 0.074 | H13: =G13*10000 -> 740 | I13: 100
A14: 101601 | B14: 嫦娥 | C14: =VLOOKUP(B14,[2]英雄技能!$D:$E,2,0) -> #N/A | D14: 5 | E14: 0.0003 | F14: =IF(D14=3,E14/0.8,IF(D14=4,E14/0.15,E14/0.05)) -> 0.006 | G14: =ROUND(F14,4) -> 0.006 | H14: =G14*10000 -> 60 | I14: 10
A15: 101701 | B15: 申空豹 | C15: =VLOOKUP(B15,[2]英雄技能!$D:$E,2,0) -> #N/A | D15: 5 | E15: 0.0003 | F15: =IF(D15=3,E15/0.8,IF(D15=4,E15/0.15,E15/0.05)) -> 0.006 | G15: =ROUND(F15,4) -> 0.006 | H15: =G15*10000 -> 60 | I15: 10
A16: 101801 | B16: 后羿 | C16: =VLOOKUP(B16,[2]英雄技能!$D:$E,2,0) -> #N/A | D16: 5 | E16: 0.00074 | F16: =IF(D16=3,E16/0.8,IF(D16=4,E16/0.15,E16/0.05)) -> 0.0148 | G16: =ROUND(F16,4) -> 0.0148 | H16: =G16*10000 -> 148 | I16: 30
A17: 101901 | B17: 李靖 | C17: =VLOOKUP(B17,[2]英雄技能!$D:$E,2,0) -> #N/A | D17: 5 | E17: 0.0003 | F17: =IF(D17=3,E17/0.8,IF(D17=4,E17/0.15,E17/0.05)) -> 0.006 | G17: =ROUND(F17,4) -> 0.006 | H17: =G17*10000 -> 60 | I17: 10
A18: 102001 | B18: 哪吒 | C18: =VLOOKUP(B18,[2]英雄技能!$D:$E,2,0) -> #N/A | D18: 5 | E18: 0.0003 | F18: =IF(D18=3,E18/0.8,IF(D18=4,E18/0.15,E18/0.05)) -> 0.006 | G18: =ROUND(F18,4) -> 0.006 | H18: =G18*10000 -> 60 | I18: 10
A19: 102101 | B19: 姜子牙 | C19: =VLOOKUP(B19,[2]英雄技能!$D:$E,2,0) -> #N/A | D19: 5 | E19: 0.00074 | F19: =IF(D19=3,E19/0.8,IF(D19=4,E19/0.15,E19/0.05)) -> 0.0148 | G19: =ROUND(F19,4) -> 0.0148 | H19: =G19*10000 -> 148 | I19: 30
A20: 102201 | B20: 雷震子 | C20: =VLOOKUP(B20,[2]英雄技能!$D:$E,2,0) -> #N/A | D20: 5 | E20: 0.0037 | F20: =IF(D20=3,E20/0.8,IF(D20=4,E20/0.15,E20/0.05)) -> 0.074 | G20: =ROUND(F20,4) -> 0.074 | H20: =G20*10000 -> 740 | I20: 100
A21: 200401 | B21: 金童 | C21: =VLOOKUP(B21,[2]英雄技能!$D:$E,2,0) -> #N/A | D21: 3 | E21: 0.047 | F21: =IF(D21=3,E21/0.8,IF(D21=4,E21/0.15,E21/0.05)) -> 0.05875 | G21: =ROUND(F21,4) -> 0.0588 | H21: =G21*10000 -> 588 | I21: 1500
A22: 200501 | B22: 玉女 | C22: =VLOOKUP(B22,[2]英雄技能!$D:$E,2,0) -> #N/A | D22: 3 | E22: 0.047 | F22: =IF(D22=3,E22/0.8,IF(D22=4,E22/0.15,E22/0.05)) -> 0.05875 | G22: =ROUND(F22,4) -> 0.0588 | H22: =G22*10000 -> 588 | I22: 1500
A23: 200601 | B23: 青宵 | C23: =VLOOKUP(B23,[2]英雄技能!$D:$E,2,0) -> #N/A | D23: 3 | E23: 0.047 | F23: =IF(D23=3,E23/0.8,IF(D23=4,E23/0.15,E23/0.05)) -> 0.05875 | G23: =ROUND(F23,4) -> 0.0588 | H23: =G23*10000 -> 588 | I23: 1500
... A25: 200801 | B25: 白龙 | C25: =VLOOKUP(B25,[2]英雄技能!$D:$E,2,0) -> #N/A | D25: 3 | E25: 0.047 | F25: =IF(D25=3,E25/0.8,IF(D25=4,E25/0.15,E25/0.05)) -> 0.05875 | G25: =ROUND(F25,4) -> 0.0588 | H25: =G25*10000 -> 588 | I25: 1500
A26: 200901 | B26: 太白金星 | C26: =VLOOKUP(B26,[2]英雄技能!$D:$E,2,0) -> #N/A | D26: 4 | E26: 0.00667 | F26: =IF(D26=3,E26/0.8,IF(D26=4,E26/0.15,E26/0.05)) -> 0.044466667 | G26: =ROUND(F26,4) -> 0.0445 | H26: =G26*10000 -> 445 | I26: 188 | R26: =30000*0.05 -> 1500
A27: 201001 | B27: 月老 | C27: =VLOOKUP(B27,[2]英雄技能!$D:$E,2,0) -> #N/A | D27: 4 | E27: 0.00667 | F27: =IF(D27=3,E27/0.8,IF(D27=4,E27/0.15,E27/0.05)) -> 0.044466667 | G27: =ROUND(F27,4) -> 0.0445 | H27: =G27*10000 -> 445 | I27: 188
A28: 201101 | B28: 织女 | C28: =VLOOKUP(B28,[2]英雄技能!$D:$E,2,0) -> #N/A | D28: 4 | E28: 0.00667 | F28: =IF(D28=3,E28/0.8,IF(D28=4,E28/0.15,E28/0.05)) -> 0.044466667 | G28: =ROUND(F28,4) -> 0.0445 | H28: =G28*10000 -> 445 | I28: 188
A29: 201201 | B29: 河伯 | C29: =VLOOKUP(B29,[2]英雄技能!$D:$E,2,0) -> #N/A | D29: 4 | E29: 0.00667 | F29: =IF(D29=3,E29/0.8,IF(D29=4,E29/0.15,E29/0.05)) -> 0.044466667 | G29: =ROUND(F29,4) -> 0.0445 | H29: =G29*10000 -> 445 | I29: 188
A30: 201301 | B30: 雨师 | C30: =VLOOKUP(B30,[2]英雄技能!$D:$E,2,0) -> #N/A | D30: 4 | E30: 0.00667 | F30: =IF(D30=3,E30/0.8,IF(D30=4,E30/0.15,E30/0.05)) -> 0.044466667 | G30: =ROUND(F30,4) -> 0.0445 | H30: =G30*10000 -> 445 | I30: 188
A31: 201401 | B31: 卷帘大将 | C31: =VLOOKUP(B31,[2]英雄技能!$D:$E,2,0) -> #N/A | D31: 5 | E31: 0.0037 | F31: =IF(D31=3,E31/0.8,IF(D31=4,E31/0.15,E31/0.05)) -> 0.074 | G31: =ROUND(F31,4) -> 0.074 | H31: =G31*10000 -> 740 | I31: 100
A32: 201501 | B32: 天蓬元帅 | C32: =VLOOKUP(B32,[2]英雄技能!$D:$E,2,0) -> #N/A | D32: 5 | E32: 0.0003 | F32: =IF(D32=3,E32/0.8,IF(D32=4,E32/0.15,E32/0.05)) -> 0.006 | G32: =ROUND(F32,4) -> 0.006 | H32: =G32*10000 -> 60 | I32: 10
A33: 201601 | B33: 南极仙翁 | C33: =VLOOKUP(B33,[2]英雄技能!$D:$E,2,0) -> #N/A | D33: 5 | E33: 0.00074 | F33: =IF(D33=3,E33/0.8,IF(D33=4,E33/0.15,E33/0.05)) -> 0.0148 | G33: =ROUND(F33,4) -> 0.0148 | H33: =G33*10000 -> 148 | I33: 30
A34: 201701 | B34: 财神 | C34: =VLOOKUP(B34,[2]英雄技能!$D:$E,2,0) -> #N/A | D34: 5 | E34: 0.0037 | F34: =IF(D34=3,E34/0.8,IF(D34=4,E34/0.15,E34/0.05)) -> 0.074 | G34: =ROUND(F34,4) -> 0.074 | H34: =G34*10000 -> 740 | I34: 100
A35: 201801 | B35: 斗战胜佛 | C35: =VLOOKUP(B35,[2]英雄技能!$D:$E,2,0) -> #N/A | D35: 5 | E35: 0.0003 | F35: =IF(D35=3,E35/0.8,IF(D35=4,E35/0.15,E35/0.05)) -> 0.006 | G35: =ROUND(F35,4) -> 0.006 | H35: =G35*10000 -> 60 | I35: 10
A36: 201901 | B36: 太乙真人 | C36: =VLOOKUP(B36,[2]英雄技能!$D:$E,2,0) -> #N/A | D36: 5 | E36: 0.0003 | F36: =IF(D36=3,E36/0.8,IF(D36=4,E36/0.15,E36/0.05)) -> 0.006 | G36: =ROUND(F36,4) -> 0.006 | H36: =G36*10000 -> 60 | I36: 10
A37: 202001 | B37: 太上老君 | C37: =VLOOKUP(B37,[2]英雄技能!$D:$E,2,0) -> #N/A | D37: 5 | E37: 0.00074 | F37: =IF(D37=3,E37/0.8,IF(D37=4,E37/0.15,E37/0.05)) -> 0.0148 | G37: =ROUND(F37,4) -> 0.0148 | H37: =G37*10000 -> 148 | I37: 30
A38: 202101 | B38: 元始天尊 | C38: =VLOOKUP(B38,[2]英雄技能!$D:$E,2,0) -> #N/A | D38: 5 | E38: 0.00074 | F38: =IF(D38=3,E38/0.8,IF(D38=4,E38/0.15,E38/0.05)) -> 0.0148 | G38: =ROUND(F38,4) -> 0.0148 | H38: =G38*10000 -> 148 | I38: 30
... A80: 500801 | B80: 刑天 | C80: =VLOOKUP(B80,[2]英雄技能!$D:$E,2,0) -> #N/A | D80: 5 | E80: 0.00018 | F80: =IF(D80=3,E80/0.8,IF(D80=4,E80/0.15,E80/0.05)) -> 0.0036 | G80: =ROUND(F80,4) -> 0.0036 | H80: =G80*10000 -> 36 | I80: 10
A81: 500901 | B81: 魔·悟空 | C81: 哈迪斯 | D81: 5 | E81: 0.00018 | F81: =IF(D81=3,E81/0.8,IF(D81=4,E81/0.15,E81/0.05)) -> 0.0036 | G81: =ROUND(F81,4) -> 0.0036 | H81: =G81*10000 -> 36 | I81: 10
A82: 501001 | B82: 黄泉 | C82: =VLOOKUP(B82,[2]英雄技能!$D:$E,2,0) -> #N/A | D82: 5 | E82: 0.00154 | F82: =IF(D82=3,E82/0.8,IF(D82=4,E82/0.15,E82/0.05)) -> 0.0308 | G82: =ROUND(F82,4) -> 0.0308 | H82: =G82*10000 -> 308 | I82: 40
...

Sheet Sheet(积分召唤概率)
A1: 英雄ID | B1: 名字 | C1: 闪烁之光角色 | D1: 星级 | E1: 概率 | F1: 子包概率 | G1: 取后四位 | H1: 万分比计算 | I1: 修正
A2: 101401 | B2: 杨戬 | C2: =VLOOKUP(B2,[2]英雄技能!$D:$E,2,0) -> #N/A | D2: 5 | E2: 0.013 | F2: =E2 -> 0.013 | G2: =ROUND(F2,4) -> 0.013 | H2: =G2*10000 -> 130 | I2: 140
A3: 101501 | B3: 邓婵玉 | C3: =VLOOKUP(B3,[2]英雄技能!$D:$E,2,0) -> #N/A | D3: 5 | E3: 0.065 | F3: =E3 -> 0.065 | G3: =ROUND(F3,4) -> 0.065 | H3: =G3*10000 -> 650 | I3: 650
A4: 101601 | B4: 嫦娥 | C4: =VLOOKUP(B4,[2]英雄技能!$D:$E,2,0) -> #N/A | D4: 5 | E4: 0.005 | F4: =E4 -> 0.005 | G4: =ROUND(F4,4) -> 0.005 | H4: =G4*10000 -> 50 | I4: 50
A5: 101701 | B5: 申空豹 | C5: =VLOOKUP(B5,[2]英雄技能!$D:$E,2,0) -> #N/A | D5: 5 | E5: 0.005 | F5: =E5 -> 0.005 | G5: =ROUND(F5,4) -> 0.005 | H5: =G5*10000 -> 50 | I5: 50
A6: 101801 | B6: 后羿 | C6: =VLOOKUP(B6,[2]英雄技能!$D:$E,2,0) -> #N/A | D6: 5 | E6: 0.013 | F6: =E6 -> 0.013 | G6: =ROUND(F6,4) -> 0.013 | H6: =G6*10000 -> 130 | I6: 140
A7: 101901 | B7: 李靖 | C7: =VLOOKUP(B7,[2]英雄技能!$D:$E,2,0) -> #N/A | D7: 5 | E7: 0.005 | F7: =E7 -> 0.005 | G7: =ROUND(F7,4) -> 0.005 | H7: =G7*10000 -> 50 | I7: 50
A8: 102001 | B8: 哪吒 | C8: =VLOOKUP(B8,[2]英雄技能!$D:$E,2,0) -> #N/A | D8: 5 | E8: 0.005 | F8: =E8 -> 0.005 | G8: =ROUND(F8,4) -> 0.005 | H8: =G8*10000 -> 50 | I8: 50
A9: 102101 | B9: 姜子牙 | C9: =VLOOKUP(B9,[2]英雄技能!$D:$E,2,0) -> #N/A | D9: 5 | E9: 0.013 | F9: =E9 -> 0.013 | G9: =ROUND(F9,4) -> 0.013 | H9: =G9*10000 -> 130 | I9: 140
A10: 102201 | B10: 雷震子 | C10: =VLOOKUP(B10,[2]英雄技能!$D:$E,2,0) -> #N/A | D10: 5 | E10: 0.065 | F10: =E10 -> 0.065 | G10: =ROUND(F10,4) -> 0.065 | H10: =G10*10000 -> 650 | I10: 650
A11: 201401 | B11: 卷帘大将 | C11: =VLOOKUP(B11,[2]英雄技能!$D:$E,2,0) -> #N/A | D11: 5 | E11: 0.065 | F11: =E11 -> 0.065 | G11: =ROUND(F11,4) -> 0.065 | H11: =G11*10000 -> 650 | I11: 650
A12: 201501 | B12: 天蓬元帅 | C12: =VLOOKUP(B12,[2]英雄技能!$D:$E,2,0) -> #N/A | D12: 5 | E12: 0.005 | F12: =E12 -> 0.005 | G12: =ROUND(F12,4) -> 0.005 | H12: =G12*10000 -> 50 | I12: 50
A13: 201601 | B13: 南极仙翁 | C13: =VLOOKUP(B13,[2]英雄技能!$D:$E,2,0) -> #N/A | D13: 5 | E13: 0.013 | F13: =E13 -> 0.013 | G13: =ROUND(F13,4) -> 0.013 | H13: =G13*10000 -> 130 | I13: 140
... A40: 500801 | B40: 刑天 | C40: =VLOOKUP(B40,[2]英雄技能!$D:$E,2,0) -> #N/A | D40: 5 | E40: 0.00438 | F40: =E40 -> 0.00438 | G40: =ROUND(F40,4) -> 0.0044 | H40: =G40*10000 -> 44 | I40: 50
A41: 500901 | B41: 魔·悟空 | C41: 哈迪斯 | D41: 5 | E41: 0.00438 | F41: =E41 -> 0.00438 | G41: =ROUND(F41,4) -> 0.0044 | H41: =G41*10000 -> 44 | I41: 50
A42: 501001 | B42: 黄泉 | C42: =VLOOKUP(B42,[2]英雄技能!$D:$E,2,0) -> #N/A | D42: 5 | E42: 0.06374 | F42: =E42 -> 0.06374 | G42: =ROUND(F42,4) -> 0.0637 | H42: =G42*10000 -> 637 | I42: 650
A43: 501101 | B43: 阎君 | C43: =VLOOKUP(B43,[2]英雄技能!$D:$E,2,0) -> #N/A | D43: 5 | E43: 0.06374 | F43: =E43 -> 0.06374 | G43: =ROUND(F43,4) -> 0.0637 | H43: =G43*10000 -> 637 | I43: 650
A44: 501201 | B44: 东皇太一 | C44: =VLOOKUP(B44,[2]英雄技能!$D:$E,2,0) -> #N/A | D44: 5 | E44: 0.012 | F44: =E44 -> 0.012 | G44: =ROUND(F44,4) -> 0.012 | H44: =G44*10000 -> 120 | I44: 120
E46: =SUM(E2:E44) -> 0.98124 | I46: =SUM(I2:I44) -> 10000

Sheet Sheet1
