Workbook

Sheet 重置基础
A1: 活动ID | B1: 活动名称 | C1: 开启天数 | D1: 开启时间 | E1: 结束天数 | F1: 结束时间 | G1: 重置分组 | H1: 图标 | I1: 活动类型 | J1: 功能ID
A2: 10001 | B2: Tiên Khí đổi thành kỳ 1 | C2: 29 | D2: 00:00:00 | E2: 35 | F2: 23:59:59 | G2: 1 | H2: 1073 | I2: 7 | J2: 18801
A3: 10002 | B3: Tiên Khí đổi thành kỳ 2 | C3: 50 | D3: 00:00:00 | E3: 56 | F3: 23:59:59 | G3: 1 | H3: 1073 | I3: 7 | J3: 18801
A4: 10003 | B4: Tiên Khí đổi thành kỳ 3 | C4: 64 | D4: 00:00:00 | E4: 70 | F4: 23:59:59 | G4: 1 | H4: 1073 | I4: 7 | J4: 18801
A5: 10004 | B5: Tiên Khí đổi thành kỳ 4 | C5: 36 | D5: 00:00:00 | E5: 42 | F5: 23:59:59 | G5: 1 | H5: 1073 | I5: 7 | J5: 18801
A6: 10005 | B6: Tiên Khí đổi thành kỳ 5 | C6: 43 | D6: 00:00:00 | E6: 49 | F6: 23:59:59 | G6: 1 | H6: 1073 | I6: 7 | J6: 18801
A7: 10006 | B7: Tiên Khí đổi thành kỳ 6 | C7: 57 | D7: 00:00:00 | E7: 63 | F7: 23:59:59 | G7: 1 | H7: 1073 | I7: 7 | J7: 18801
A8: 10007 | B8: Tiên Khí đổi thành kỳ 7 | C8: 71 | D8: 00:00:00 | E8: 77 | F8: 23:59:59 | G8: 1 | H8: 1073 | I8: 7 | J8: 18801
A9: 10008 | B9: Tiên Khí đổi thành kỳ 8 | C9: 78 | D9: 00:00:00 | E9: 84 | F9: 23:59:59 | G9: 1 | H9: 1073 | I9: 7 | J9: 18801
A10: 10009 | B10: Tiên Khí đổi thành kỳ 9 | C10: 85 | D10: 00:00:00 | E10: 91 | F10: 23:59:59 | G10: 1 | H10: 1073 | I10: 7 | J10: 18801
A11: 10010 | B11: Tiên Khí đổi thành kỳ 10 | C11: 92 | D11: 00:00:00 | E11: 98 | F11: 23:59:59 | G11: 1 | H11: 1073 | I11: 7 | J11: 18801
A12: 10011 | B12: Tiên Khí đổi thành kỳ 11 | C12: 99 | D12: 00:00:00 | E12: 105 | F12: 23:59:59 | G12: 1 | H12: 1073 | I12: 7 | J12: 18801
A13: 10012 | B13: Tiên Khí đổi thành kỳ 12 | C13: 106 | D13: 00:00:00 | E13: 112 | F13: 23:59:59 | G13: 1 | H13: 1073 | I13: 7 | J13: 18801
... A36: 10035 | B36: Tiên Khí đổi thành kỳ 35 | C36: 267 | D36: 00:00:00 | E36: 273 | F36: 23:59:59 | G36: 1 | H36: 1073 | I36: 7 | J36: 18801
A37: 10036 | B37: Tiên Khí đổi thành kỳ 36 | C37: =C36+7 -> 274 | D37: 00:00:00 | E37: =E36+7 -> 280 | F37: 23:59:59 | G37: 1 | H37: 1073 | I37: 7 | J37: 18801
A38: 10037 | B38: Tiên Khí đổi thành kỳ 37 | C38: =C37+7 -> 281 | D38: 00:00:00 | E38: =E37+7 -> 287 | F38: 23:59:59 | G38: 1 | H38: 1073 | I38: 7 | J38: 18801
A39: 10038 | B39: Tiên Khí đổi thành kỳ 38 | C39: =C38+7 -> 288 | D39: 00:00:00 | E39: =E38+7 -> 294 | F39: 23:59:59 | G39: 1 | H39: 1073 | I39: 7 | J39: 18801
A40: 10039 | B40: Tiên Khí đổi thành kỳ 39 | C40: =C39+7 -> 295 | D40: 00:00:00 | E40: =E39+7 -> 301 | F40: 23:59:59 | G40: 1 | H40: 1073 | I40: 7 | J40: 18801
A41: 10040 | B41: Tiên Khí đổi thành kỳ 40 | C41: =C40+7 -> 302 | D41: 00:00:00 | E41: =E40+7 -> 308 | F41: 23:59:59 | G41: 1 | H41: 1073 | I41: 7 | J41: 18801
A42: 10041 | B42: Tiên Khí đổi thành kỳ 41 | C42: =C41+7 -> 309 | D42: 00:00:00 | E42: =E41+7 -> 315 | F42: 23:59:59 | G42: 1 | H42: 1073 | I42: 7 | J42: 18801
A43: 10042 | B43: Tiên Khí đổi thành kỳ 42 | C43: =C42+7 -> 316 | D43: 00:00:00 | E43: =E42+7 -> 322 | F43: 23:59:59 | G43: 1 | H43: 1073 | I43: 7 | J43: 18801
A44: 10043 | B44: Tiên Khí đổi thành kỳ 43 | C44: =C43+7 -> 323 | D44: 00:00:00 | E44: =E43+7 -> 329 | F44: 23:59:59 | G44: 1 | H44: 1073 | I44: 7 | J44: 18801
A45: 10044 | B45: Tiên Khí đổi thành kỳ 44 | C45: =C44+7 -> 330 | D45: 00:00:00 | E45: =E44+7 -> 336 | F45: 23:59:59 | G45: 1 | H45: 1073 | I45: 7 | J45: 18801
A46: 10045 | B46: Tiên Khí đổi thành kỳ 45 | C46: =C45+7 -> 337 | D46: 00:00:00 | E46: =E45+7 -> 343 | F46: 23:59:59 | G46: 1 | H46: 1073 | I46: 7 | J46: 18801
A47: 10046 | B47: Tiên Khí đổi thành kỳ 46 | C47: =C46+7 -> 344 | D47: 00:00:00 | E47: =E46+7 -> 350 | F47: 23:59:59 | G47: 1 | H47: 1073 | I47: 7 | J47: 18801
A48: 10047 | B48: Tiên Khí đổi thành kỳ 47 | C48: =C47+7 -> 351 | D48: 00:00:00 | E48: =E47+7 -> 357 | F48: 23:59:59 | G48: 1 | H48: 1073 | I48: 7 | J48: 18801
... A185: 10184 | B185: Tiên Khí đổi thành kỳ 184 | C185: =C184+7 -> 1310 | D185: 00:00:00 | E185: =E184+7 -> 1316 | F185: 23:59:59 | G185: 1 | H185: 1073 | I185: 7 | J185: 18801

Sheet 重置消耗
A1: ID | B1: 类型 | C1: 消耗道具 | D1: 重置分组 | E1: 目标奖池分组 | F1: 目标仙器类型
A2: 10001 | B2: 1 | C2: 3:100087:50 | D2: 1 | E2: 1 | F2: 1#2#3
A3: 10002 | B3: 2 | C3: 3:100087:50 | D3: 1 | E3: 1 | F3: 1#2#3
A4: 10003 | B4: 3 | C4: 3:100087:50 | D4: 1 | E4: 1 | F4: 1#2#3
A5: 10004 | B5: 4 | C5: 3:100087:100 | D5: 1 | E5: 2 | F5: 4#5
A6: 10005 | B6: 5 | C6: 3:100087:100 | D6: 1 | E6: 2 | F6: 4#5

Sheet 重置奖池
A1: ID | B1: 目标奖池分组 | C1: 目标ID | D1: *名称 | E1: 权重 | F1: 图片
A2: 1 | B2: 1 | C2: 1000101 | D2: =VLOOKUP(C2,[1]仙器基础!$A:$C,3,0) -> 龙王篓 | E2: 1000 | F2: XQ1000101
A3: 2 | B3: 1 | C3: 2000101 | D3: =VLOOKUP(C3,[1]仙器基础!$A:$C,3,0) -> 精金铜钱 | E3: 1000 | F3: XQ2000101
A4: 3 | B4: 1 | C4: 3000101 | D4: =VLOOKUP(C4,[1]仙器基础!$A:$C,3,0) -> 火缨枪 | E4: 1000 | F4: XQ3000101
A5: 4 | B5: 1 | C5: 6000101 | D5: =VLOOKUP(C5,[1]仙器基础!$A:$C,3,0) -> 落日弓 | E5: 1000 | F5: XQ6000101
A6: 5 | B6: 1 | C6: 7000101 | D6: =VLOOKUP(C6,[1]仙器基础!$A:$C,3,0) -> 上宝沁金耙 | E6: 1000 | F6: XQ7000101
A7: 6 | B7: 1 | C7: 8000101 | D7: =VLOOKUP(C7,[1]仙器基础!$A:$C,3,0) -> 彩云飘 | E7: 1000 | F7: XQ8000101
A8: 7 | B8: 1 | C8: 11000101 | D8: =VLOOKUP(C8,[1]仙器基础!$A:$C,3,0) -> 月华 | E8: 1000 | F8: XQ11000102
A9: 8 | B9: 1 | C9: 13000101 | D9: =VLOOKUP(C9,[1]仙器基础!$A:$C,3,0) -> 混天绫 | E9: 600 | F9: XQ13000101
A10: 9 | B10: 1 | C10: 16000101 | D10: =VLOOKUP(C10,[1]仙器基础!$A:$C,3,0) -> 海盐珍珠蚌 | E10: 1000 | F10: XQ16000101
A11: 10 | B11: 1 | C11: 18000101 | D11: =VLOOKUP(C11,[1]仙器基础!$A:$C,3,0) -> 浮世清欢 | E11: 1000 | F11: XQ18000101
A12: 11 | B12: 1 | C12: 19000101 | D12: =VLOOKUP(C12,[1]仙器基础!$A:$C,3,0) -> 如意金箍棒 | E12: 1000 | F12: XQ19000101
A13: 12 | B13: 1 | C13: 22000101 | D13: =VLOOKUP(C13,[1]仙器基础!$A:$C,3,0) -> 剑匣 | E13: 1000 | F13: XQ22000101
... A17: 16 | B17: 1 | C17: 32000101 | D17: =VLOOKUP(C17,[1]仙器基础!$A:$C,3,0) -> 青萍 | E17: 1000 | F17: XQ32000101
A18: 17 | B18: 2 | C18: 4000101 | D18: =VLOOKUP(C18,[1]仙器基础!$A:$C,3,0) -> 太虚神甲 | E18: 1000 | F18: XQ4000101 | G18: =E18/SUM(E$18:E$33) -> 0.078740157
A19: 18 | B19: 2 | C19: 5000101 | D19: =VLOOKUP(C19,[1]仙器基础!$A:$C,3,0) -> 东皇钟 | E19: 1000 | F19: XQ5000101 | G19: =E19/SUM(E$18:E$33) -> 0.078740157
A20: 19 | B20: 2 | C20: 9000101 | D20: =VLOOKUP(C20,[1]仙器基础!$A:$C,3,0) -> 神农鼎 | E20: 500 | F20: XQ9000101 | G20: =E20/SUM(E$18:E$33) -> 0.039370079
A21: 20 | B21: 2 | C21: 10000101 | D21: =VLOOKUP(C21,[1]仙器基础!$A:$C,3,0) -> 忘忧 | E21: 1000 | F21: XQ10000101 | G21: =E21/SUM(E$18:E$33) -> 0.078740157
A22: 21 | B22: 2 | C22: 12000101 | D22: =VLOOKUP(C22,[1]仙器基础!$A:$C,3,0) -> 老龙布雨 | E22: 600 | F22: XQ12000101 | G22: =E22/SUM(E$18:E$33) -> 0.047244094
A23: 22 | B23: 2 | C23: 14000101 | D23: =VLOOKUP(C23,[1]仙器基础!$A:$C,3,0) -> 虎魄刀 | E23: 600 | F23: XQ14000101 | G23: =E23/SUM(E$18:E$33) -> 0.047244094
A24: 23 | B24: 2 | C24: 15000101 | D24: =VLOOKUP(C24,[1]仙器基础!$A:$C,3,0) -> 梦境遗珠 | E24: 1000 | F24: XQ15000101 | G24: =E24/SUM(E$18:E$33) -> 0.078740157
A25: 24 | B25: 2 | C25: 17000101 | D25: =VLOOKUP(C25,[1]仙器基础!$A:$C,3,0) -> 随心铁杆兵 | E25: 500 | F25: XQ17000101 | G25: =E25/SUM(E$18:E$33) -> 0.039370079
A26: 25 | B26: 2 | C26: 20000101 | D26: =VLOOKUP(C26,[1]仙器基础!$A:$C,3,0) -> 永夜 | E26: 500 | F26: XQ20000101 | G26: =E26/SUM(E$18:E$33) -> 0.039370079
A27: 26 | B27: 2 | C27: 21000101 | D27: =VLOOKUP(C27,[1]仙器基础!$A:$C,3,0) -> 雪花翎 | E27: 500 | F27: XQ21000101 | G27: =E27/SUM(E$18:E$33) -> 0.039370079
A28: 27 | B28: 2 | C28: 23000101 | D28: =VLOOKUP(C28,[1]仙器基础!$A:$C,3,0) -> 斩魂 | E28: 500 | F28: XQ23000101 | G28: =E28/SUM(E$18:E$33) -> 0.039370079
A29: 28 | B29: 2 | C29: 24000101 | D29: =VLOOKUP(C29,[1]仙器基础!$A:$C,3,0) -> 螭龙印 | E29: 1000 | F29: XQ24000101 | G29: =E29/SUM(E$18:E$33) -> 0.078740157
... A33: 32 | B33: 2 | C33: 28000101 | D33: =VLOOKUP(C33,[1]仙器基础!$A:$C,3,0) -> 暮光 | E33: 1000 | F33: XQ28000101 | G33: =E33/SUM(E$18:E$33) -> 0.078740157
A34: 33 | B34: 1 | C34: 33000101 | D34: 李靖的仙器 | E34: 1000 | F34: XQ33000101 | G34: =E34/SUM(E$18:E$33) -> 0.078740157
A35: 34 | B35: 1 | C35: 34000101 | D35: 玄奘的仙器 | E35: 1000 | F35: XQ34000101 | G35: =E35/SUM(E$18:E$33) -> 0.078740157
A36: 35 | B36: 1 | C36: 35000101 | D36: 白骨夫人的仙器 | E36: 1000 | F36: XQ35000101 | G36: =E36/SUM(E$18:E$33) -> 0.078740157
A37: 36 | B37: 1 | C37: 36000101 | D37: 孔宣的仙器 | E37: 600 | F37: XQ36000101 | G37: =E37/SUM(E$18:E$33) -> 0.047244094
A38: 37 | B38: 1 | C38: 37000101 | D38: 元始天尊的仙器 | E38: 1000 | F38: XQ37000101
A39: 38 | B39: 1 | C39: 38000101 | D39: 姬发的仙器 | E39: 1000 | F39: XQ38000101
A40: 39 | B40: 1 | C40: 39000101 | D40: 牛魔王的仙器 | E40: 1000 | F40: XQ39000101
A41: 40 | B41: 2 | C41: 40000101 | D41: 灵媒魔女的仙器 | E41: 500 | F41: XQ40000101
A42: 41 | B42: 2 | C42: 41000101 | D42: 冥河的仙器 | E42: 500 | F42: XQ41000101
A43: 42 | B43: 2 | C43: 42000101 | D43: 杨戬的仙器 | E43: 500 | F43: XQ42000101
A44: 43 | B44: 2 | C44: 43000101 | D44: 妈祖的仙器 | E44: 500 | F44: XQ43000101
A45: 44 | B45: 2 | C45: 45000101 | D45: 三圣母的仙器 | E45: 500 | F45: XQ45000101
A46: 45 | B46: 1 | C46: 47000101 | D46: 土地的仙器 | E46: 0 | F46: XQ47000101
...

Sheet Sheet1
A1: 原型ID | B1: 阵营
A2: 1000101 | B2: 1
A3: 2000101 | B3: 2
A4: 3000101 | B4: 3
A5: 4000101 | B5: 4
A6: 5000101 | B6: 5
A7: 6000101 | B7: 1
A8: 7000101 | B8: 2
A9: 8000101 | B9: 3
A10: 9000101 | B10: 4
A11: 10000101 | B11: 5
A12: 11000101 | B12: 1
A13: 12000101 | B13: 4
... A33: 32000101 | B33: 2
